Exception on / [GET]
Traceback (most recent call last):
  File "C:\Users\user\Desktop\kpasec22\venv\lib\site-packages\sqlalchemy\util\_collections.py", line 1008, in __call__
    return self.registry[key]
KeyError: <greenlet.greenlet object at 0x07879448 (otid=0x0788F578) current active started main>

During handling of the above exception, another exception occurred:

Traceback (most recent call last):
  File "C:\Users\user\Desktop\kpasec22\venv\lib\site-packages\flask\app.py", line 2073, in wsgi_app
    response = self.full_dispatch_request()
  File "C:\Users\user\Desktop\kpasec22\venv\lib\site-packages\flask\app.py", line 1518, in full_dispatch_request
    rv = self.handle_user_exception(e)
  File "C:\Users\user\Desktop\kpasec22\venv\lib\site-packages\flask\app.py", line 1516, in full_dispatch_request
    rv = self.dispatch_request()
  File "C:\Users\user\Desktop\kpasec22\venv\lib\site-packages\flask\app.py", line 1502, in dispatch_request
    return self.ensure_sync(self.view_functions[rule.endpoint])(**req.view_args)
  File "C:\Users\user\Desktop\kpasec22\app.py", line 91, in home
    return render_template("homepage1.html")
  File "C:\Users\user\Desktop\kpasec22\venv\lib\site-packages\flask\templating.py", line 146, in render_template
    ctx.app.update_template_context(context)
  File "C:\Users\user\Desktop\kpasec22\venv\lib\site-packages\flask\app.py", line 756, in update_template_context
    context.update(func())
  File "C:\Users\user\Desktop\kpasec22\venv\lib\site-packages\flask_login\utils.py", line 379, in _user_context_processor
    return dict(current_user=_get_user())
  File "C:\Users\user\Desktop\kpasec22\venv\lib\site-packages\flask_login\utils.py", line 346, in _get_user
    current_app.login_manager._load_user()
  File "C:\Users\user\Desktop\kpasec22\venv\lib\site-packages\flask_login\login_manager.py", line 318, in _load_user
    user = self._user_callback(user_id)
  File "C:\Users\user\Desktop\kpasec22\app.py", line 87, in load_user
    return User.query.get(int(user_id))
  File "C:\Users\user\Desktop\kpasec22\venv\lib\site-packages\flask_sqlalchemy\__init__.py", line 552, in __get__
    return type.query_class(mapper, session=self.sa.session())
  File "C:\Users\user\Desktop\kpasec22\venv\lib\site-packages\sqlalchemy\orm\scoping.py", line 47, in __call__
    sess = self.registry()
  File "C:\Users\user\Desktop\kpasec22\venv\lib\site-packages\sqlalchemy\util\_collections.py", line 1010, in __call__
    return self.registry.setdefault(key, self.createfunc())
  File "C:\Users\user\Desktop\kpasec22\venv\lib\site-packages\sqlalchemy\orm\session.py", line 4205, in __call__
    return self.class_(**local_kw)
  File "C:\Users\user\Desktop\kpasec22\venv\lib\site-packages\flask_sqlalchemy\__init__.py", line 176, in __init__
    bind = options.pop('bind', None) or db.engine
  File "C:\Users\user\Desktop\kpasec22\venv\lib\site-packages\flask_sqlalchemy\__init__.py", line 998, in engine
    return self.get_engine()
  File "C:\Users\user\Desktop\kpasec22\venv\lib\site-packages\flask_sqlalchemy\__init__.py", line 1017, in get_engine
    return connector.get_engine()
  File "C:\Users\user\Desktop\kpasec22\venv\lib\site-packages\flask_sqlalchemy\__init__.py", line 594, in get_engine
    self._engine = rv = self._sa.create_engine(sa_url, options)
  File "C:\Users\user\Desktop\kpasec22\venv\lib\site-packages\flask_sqlalchemy\__init__.py", line 1027, in create_engine
    return sqlalchemy.create_engine(sa_url, **engine_opts)
  File "<string>", line 2, in create_engine
  File "C:\Users\user\Desktop\kpasec22\venv\lib\site-packages\sqlalchemy\util\deprecations.py", line 309, in warned
    return fn(*args, **kwargs)
  File "C:\Users\user\Desktop\kpasec22\venv\lib\site-packages\sqlalchemy\engine\create.py", line 534, in create_engine
    entrypoint = u._get_entrypoint()
  File "C:\Users\user\Desktop\kpasec22\venv\lib\site-packages\sqlalchemy\engine\url.py", line 661, in _get_entrypoint
    cls = registry.load(name)
  File "C:\Users\user\Desktop\kpasec22\venv\lib\site-packages\sqlalchemy\util\langhelpers.py", line 343, in load
    raise exc.NoSuchModuleError(
sqlalchemy.exc.NoSuchModuleError: Can't load plugin: sqlalchemy.dialects:postgres
Exception on /login [POST]
Traceback (most recent call last):
  File "C:\Users\user\anaconda3\lib\site-packages\sqlalchemy\util\_collections.py", line 1008, in __call__
    return self.registry[key]
KeyError: <greenlet.greenlet object at 0x000002A277171300 (otid=0x000002A277172080) current active started main>

During handling of the above exception, another exception occurred:

Traceback (most recent call last):
  File "C:\Users\user\anaconda3\lib\site-packages\flask\app.py", line 2447, in wsgi_app
    response = self.full_dispatch_request()
  File "C:\Users\user\anaconda3\lib\site-packages\flask\app.py", line 1952, in full_dispatch_request
    rv = self.handle_user_exception(e)
  File "C:\Users\user\anaconda3\lib\site-packages\flask\app.py", line 1821, in handle_user_exception
    reraise(exc_type, exc_value, tb)
  File "C:\Users\user\anaconda3\lib\site-packages\flask\_compat.py", line 39, in reraise
    raise value
  File "C:\Users\user\anaconda3\lib\site-packages\flask\app.py", line 1950, in full_dispatch_request
    rv = self.dispatch_request()
  File "C:\Users\user\anaconda3\lib\site-packages\flask\app.py", line 1936, in dispatch_request
    return self.view_functions[rule.endpoint](**req.view_args)
  File "C:\Users\user\Desktop\kpasec22\app.py", line 165, in login
    user = User.query.filter_by(email=form.email.data.strip()).first()
  File "C:\Users\user\anaconda3\lib\site-packages\flask_sqlalchemy\__init__.py", line 552, in __get__
    return type.query_class(mapper, session=self.sa.session())
  File "C:\Users\user\anaconda3\lib\site-packages\sqlalchemy\orm\scoping.py", line 47, in __call__
    return self.registry()
  File "C:\Users\user\anaconda3\lib\site-packages\sqlalchemy\util\_collections.py", line 1010, in __call__
    return self.registry.setdefault(key, self.createfunc())
  File "C:\Users\user\anaconda3\lib\site-packages\sqlalchemy\orm\session.py", line 4101, in __call__
    return self.class_(**local_kw)
  File "C:\Users\user\anaconda3\lib\site-packages\flask_sqlalchemy\__init__.py", line 176, in __init__
    bind = options.pop('bind', None) or db.engine
  File "C:\Users\user\anaconda3\lib\site-packages\flask_sqlalchemy\__init__.py", line 998, in engine
    return self.get_engine()
  File "C:\Users\user\anaconda3\lib\site-packages\flask_sqlalchemy\__init__.py", line 1017, in get_engine
    return connector.get_engine()
  File "C:\Users\user\anaconda3\lib\site-packages\flask_sqlalchemy\__init__.py", line 594, in get_engine
    self._engine = rv = self._sa.create_engine(sa_url, options)
  File "C:\Users\user\anaconda3\lib\site-packages\flask_sqlalchemy\__init__.py", line 1027, in create_engine
    return sqlalchemy.create_engine(sa_url, **engine_opts)
  File "<string>", line 2, in create_engine
  File "C:\Users\user\anaconda3\lib\site-packages\sqlalchemy\util\deprecations.py", line 298, in warned
    return fn(*args, **kwargs)
  File "C:\Users\user\anaconda3\lib\site-packages\sqlalchemy\engine\create.py", line 548, in create_engine
    dbapi = dialect_cls.dbapi(**dbapi_args)
  File "C:\Users\user\anaconda3\lib\site-packages\sqlalchemy\dialects\postgresql\psycopg2.py", line 793, in dbapi
    import psycopg2
ModuleNotFoundError: No module named 'psycopg2'
Exception on /login [POST]
Traceback (most recent call last):
  File "C:\Users\user\anaconda3\lib\site-packages\sqlalchemy\engine\base.py", line 1771, in _execute_context
    self.dialect.do_execute(
  File "C:\Users\user\anaconda3\lib\site-packages\sqlalchemy\engine\default.py", line 717, in do_execute
    cursor.execute(statement, parameters)
psycopg2.OperationalError: server closed the connection unexpectedly
	This probably means the server terminated abnormally
	before or while processing the request.
server closed the connection unexpectedly
	This probably means the server terminated abnormally
	before or while processing the request.
server closed the connection unexpectedly
	This probably means the server terminated abnormally
	before or while processing the request.


The above exception was the direct cause of the following exception:

Traceback (most recent call last):
  File "C:\Users\user\anaconda3\lib\site-packages\flask\app.py", line 2447, in wsgi_app
    response = self.full_dispatch_request()
  File "C:\Users\user\anaconda3\lib\site-packages\flask\app.py", line 1952, in full_dispatch_request
    rv = self.handle_user_exception(e)
  File "C:\Users\user\anaconda3\lib\site-packages\flask\app.py", line 1821, in handle_user_exception
    reraise(exc_type, exc_value, tb)
  File "C:\Users\user\anaconda3\lib\site-packages\flask\_compat.py", line 39, in reraise
    raise value
  File "C:\Users\user\anaconda3\lib\site-packages\flask\app.py", line 1950, in full_dispatch_request
    rv = self.dispatch_request()
  File "C:\Users\user\anaconda3\lib\site-packages\flask\app.py", line 1936, in dispatch_request
    return self.view_functions[rule.endpoint](**req.view_args)
  File "C:\Users\user\Desktop\kpasec22\app.py", line 165, in login
    user = User.query.filter_by(email=form.email.data.strip()).first()
  File "C:\Users\user\anaconda3\lib\site-packages\sqlalchemy\orm\query.py", line 2763, in first
    return self.limit(1)._iter().first()
  File "C:\Users\user\anaconda3\lib\site-packages\sqlalchemy\orm\query.py", line 2847, in _iter
    result = self.session.execute(
  File "C:\Users\user\anaconda3\lib\site-packages\sqlalchemy\orm\session.py", line 1689, in execute
    result = conn._execute_20(statement, params or {}, execution_options)
  File "C:\Users\user\anaconda3\lib\site-packages\sqlalchemy\engine\base.py", line 1583, in _execute_20
    return meth(self, args_10style, kwargs_10style, execution_options)
  File "C:\Users\user\anaconda3\lib\site-packages\sqlalchemy\sql\elements.py", line 323, in _execute_on_connection
    return connection._execute_clauseelement(
  File "C:\Users\user\anaconda3\lib\site-packages\sqlalchemy\engine\base.py", line 1452, in _execute_clauseelement
    ret = self._execute_context(
  File "C:\Users\user\anaconda3\lib\site-packages\sqlalchemy\engine\base.py", line 1814, in _execute_context
    self._handle_dbapi_exception(
  File "C:\Users\user\anaconda3\lib\site-packages\sqlalchemy\engine\base.py", line 1995, in _handle_dbapi_exception
    util.raise_(
  File "C:\Users\user\anaconda3\lib\site-packages\sqlalchemy\util\compat.py", line 207, in raise_
    raise exception
  File "C:\Users\user\anaconda3\lib\site-packages\sqlalchemy\engine\base.py", line 1771, in _execute_context
    self.dialect.do_execute(
  File "C:\Users\user\anaconda3\lib\site-packages\sqlalchemy\engine\default.py", line 717, in do_execute
    cursor.execute(statement, parameters)
sqlalchemy.exc.OperationalError: (psycopg2.OperationalError) server closed the connection unexpectedly
	This probably means the server terminated abnormally
	before or while processing the request.
server closed the connection unexpectedly
	This probably means the server terminated abnormally
	before or while processing the request.
server closed the connection unexpectedly
	This probably means the server terminated abnormally
	before or while processing the request.

[SQL: SELECT "user".id AS user_id, "user".date AS user_date, "user".username AS user_username, "user".email AS user_email, "user".password AS user_password, "user".is_admin AS user_is_admin, "user".function AS user_function, "user".approval AS user_approval 
FROM "user" 
WHERE "user".email = %(email_1)s 
 LIMIT %(param_1)s]
[parameters: {'email_1': 'kuminewton@gmail.com', 'param_1': 1}]
(Background on this error at: https://sqlalche.me/e/14/e3q8)
Exception on /accountant_dashboard/student_stats [GET]
Traceback (most recent call last):
  File "C:\Users\user\anaconda3\lib\site-packages\sqlalchemy\engine\base.py", line 1771, in _execute_context
    self.dialect.do_execute(
  File "C:\Users\user\anaconda3\lib\site-packages\sqlalchemy\engine\default.py", line 717, in do_execute
    cursor.execute(statement, parameters)
psycopg2.OperationalError: terminating connection due to administrator command
SSL connection has been closed unexpectedly


The above exception was the direct cause of the following exception:

Traceback (most recent call last):
  File "C:\Users\user\anaconda3\lib\site-packages\flask\app.py", line 2447, in wsgi_app
    response = self.full_dispatch_request()
  File "C:\Users\user\anaconda3\lib\site-packages\flask\app.py", line 1952, in full_dispatch_request
    rv = self.handle_user_exception(e)
  File "C:\Users\user\anaconda3\lib\site-packages\flask\app.py", line 1821, in handle_user_exception
    reraise(exc_type, exc_value, tb)
  File "C:\Users\user\anaconda3\lib\site-packages\flask\_compat.py", line 39, in reraise
    raise value
  File "C:\Users\user\anaconda3\lib\site-packages\flask\app.py", line 1950, in full_dispatch_request
    rv = self.dispatch_request()
  File "C:\Users\user\anaconda3\lib\site-packages\flask\app.py", line 1936, in dispatch_request
    return self.view_functions[rule.endpoint](**req.view_args)
  File "C:\Users\user\anaconda3\lib\site-packages\flask_login\utils.py", line 270, in decorated_view
    elif not current_user.is_authenticated:
  File "C:\Users\user\anaconda3\lib\site-packages\werkzeug\local.py", line 432, in __get__
    obj = instance._get_current_object()
  File "C:\Users\user\anaconda3\lib\site-packages\werkzeug\local.py", line 554, in _get_current_object
    return self.__local()  # type: ignore
  File "C:\Users\user\anaconda3\lib\site-packages\flask_login\utils.py", line 26, in <lambda>
    current_user = LocalProxy(lambda: _get_user())
  File "C:\Users\user\anaconda3\lib\site-packages\flask_login\utils.py", line 346, in _get_user
    current_app.login_manager._load_user()
  File "C:\Users\user\anaconda3\lib\site-packages\flask_login\login_manager.py", line 318, in _load_user
    user = self._user_callback(user_id)
  File "C:\Users\user\Desktop\kpasec22\app.py", line 116, in load_user
    return User.query.get(int(user_id))
  File "<string>", line 2, in get
  File "C:\Users\user\anaconda3\lib\site-packages\sqlalchemy\util\deprecations.py", line 390, in warned
    return fn(*args, **kwargs)
  File "C:\Users\user\anaconda3\lib\site-packages\sqlalchemy\orm\query.py", line 944, in get
    return self._get_impl(ident, loading.load_on_pk_identity)
  File "C:\Users\user\anaconda3\lib\site-packages\sqlalchemy\orm\query.py", line 948, in _get_impl
    return self.session._get_impl(
  File "C:\Users\user\anaconda3\lib\site-packages\sqlalchemy\orm\session.py", line 2839, in _get_impl
    return db_load_fn(
  File "C:\Users\user\anaconda3\lib\site-packages\sqlalchemy\orm\loading.py", line 557, in load_on_pk_identity
    session.execute(
  File "C:\Users\user\anaconda3\lib\site-packages\sqlalchemy\orm\session.py", line 1689, in execute
    result = conn._execute_20(statement, params or {}, execution_options)
  File "C:\Users\user\anaconda3\lib\site-packages\sqlalchemy\engine\base.py", line 1583, in _execute_20
    return meth(self, args_10style, kwargs_10style, execution_options)
  File "C:\Users\user\anaconda3\lib\site-packages\sqlalchemy\sql\elements.py", line 323, in _execute_on_connection
    return connection._execute_clauseelement(
  File "C:\Users\user\anaconda3\lib\site-packages\sqlalchemy\engine\base.py", line 1452, in _execute_clauseelement
    ret = self._execute_context(
  File "C:\Users\user\anaconda3\lib\site-packages\sqlalchemy\engine\base.py", line 1814, in _execute_context
    self._handle_dbapi_exception(
  File "C:\Users\user\anaconda3\lib\site-packages\sqlalchemy\engine\base.py", line 1995, in _handle_dbapi_exception
    util.raise_(
  File "C:\Users\user\anaconda3\lib\site-packages\sqlalchemy\util\compat.py", line 207, in raise_
    raise exception
  File "C:\Users\user\anaconda3\lib\site-packages\sqlalchemy\engine\base.py", line 1771, in _execute_context
    self.dialect.do_execute(
  File "C:\Users\user\anaconda3\lib\site-packages\sqlalchemy\engine\default.py", line 717, in do_execute
    cursor.execute(statement, parameters)
sqlalchemy.exc.OperationalError: (psycopg2.OperationalError) terminating connection due to administrator command
SSL connection has been closed unexpectedly

[SQL: SELECT "user".id AS user_id, "user".date AS user_date, "user".username AS user_username, "user".email AS user_email, "user".password AS user_password, "user".is_admin AS user_is_admin, "user".function AS user_function, "user".approval AS user_approval 
FROM "user" 
WHERE "user".id = %(pk_1)s]
[parameters: {'pk_1': 1}]
(Background on this error at: https://sqlalche.me/e/14/e3q8)
Exception on /accountant_dashboard/student_stats [GET]
Traceback (most recent call last):
  File "C:\Users\user\anaconda3\lib\site-packages\sqlalchemy\engine\base.py", line 3212, in _wrap_pool_connect
    return fn()
  File "C:\Users\user\anaconda3\lib\site-packages\sqlalchemy\pool\base.py", line 307, in connect
    return _ConnectionFairy._checkout(self)
  File "C:\Users\user\anaconda3\lib\site-packages\sqlalchemy\pool\base.py", line 767, in _checkout
    fairy = _ConnectionRecord.checkout(pool)
  File "C:\Users\user\anaconda3\lib\site-packages\sqlalchemy\pool\base.py", line 430, in checkout
    rec._checkin_failed(err, _fairy_was_created=False)
  File "C:\Users\user\anaconda3\lib\site-packages\sqlalchemy\util\langhelpers.py", line 70, in __exit__
    compat.raise_(
  File "C:\Users\user\anaconda3\lib\site-packages\sqlalchemy\util\compat.py", line 207, in raise_
    raise exception
  File "C:\Users\user\anaconda3\lib\site-packages\sqlalchemy\pool\base.py", line 427, in checkout
    dbapi_connection = rec.get_connection()
  File "C:\Users\user\anaconda3\lib\site-packages\sqlalchemy\pool\base.py", line 552, in get_connection
    self.__connect()
  File "C:\Users\user\anaconda3\lib\site-packages\sqlalchemy\pool\base.py", line 611, in __connect
    pool.logger.debug("Error on connect(): %s", e)
  File "C:\Users\user\anaconda3\lib\site-packages\sqlalchemy\util\langhelpers.py", line 70, in __exit__
    compat.raise_(
  File "C:\Users\user\anaconda3\lib\site-packages\sqlalchemy\util\compat.py", line 207, in raise_
    raise exception
  File "C:\Users\user\anaconda3\lib\site-packages\sqlalchemy\pool\base.py", line 605, in __connect
    connection = pool._invoke_creator(self)
  File "C:\Users\user\anaconda3\lib\site-packages\sqlalchemy\engine\create.py", line 578, in connect
    return dialect.connect(*cargs, **cparams)
  File "C:\Users\user\anaconda3\lib\site-packages\sqlalchemy\engine\default.py", line 584, in connect
    return self.dbapi.connect(*cargs, **cparams)
  File "C:\Users\user\anaconda3\lib\site-packages\psycopg2\__init__.py", line 122, in connect
    conn = _connect(dsn, connection_factory=connection_factory, **kwasync)
psycopg2.OperationalError: connection to server at "ec2-44-192-245-97.compute-1.amazonaws.com" (44.192.245.97), port 5432 failed: FATAL:  password authentication failed for user "rcrcittfbiapfa"
connection to server at "ec2-44-192-245-97.compute-1.amazonaws.com" (44.192.245.97), port 5432 failed: FATAL:  no pg_hba.conf entry for host "102.176.94.123", user "rcrcittfbiapfa", database "da8kfqt02ehgca", SSL off


The above exception was the direct cause of the following exception:

Traceback (most recent call last):
  File "C:\Users\user\anaconda3\lib\site-packages\flask\app.py", line 2447, in wsgi_app
    response = self.full_dispatch_request()
  File "C:\Users\user\anaconda3\lib\site-packages\flask\app.py", line 1952, in full_dispatch_request
    rv = self.handle_user_exception(e)
  File "C:\Users\user\anaconda3\lib\site-packages\flask\app.py", line 1821, in handle_user_exception
    reraise(exc_type, exc_value, tb)
  File "C:\Users\user\anaconda3\lib\site-packages\flask\_compat.py", line 39, in reraise
    raise value
  File "C:\Users\user\anaconda3\lib\site-packages\flask\app.py", line 1950, in full_dispatch_request
    rv = self.dispatch_request()
  File "C:\Users\user\anaconda3\lib\site-packages\flask\app.py", line 1936, in dispatch_request
    return self.view_functions[rule.endpoint](**req.view_args)
  File "C:\Users\user\anaconda3\lib\site-packages\flask_login\utils.py", line 270, in decorated_view
    elif not current_user.is_authenticated:
  File "C:\Users\user\anaconda3\lib\site-packages\werkzeug\local.py", line 432, in __get__
    obj = instance._get_current_object()
  File "C:\Users\user\anaconda3\lib\site-packages\werkzeug\local.py", line 554, in _get_current_object
    return self.__local()  # type: ignore
  File "C:\Users\user\anaconda3\lib\site-packages\flask_login\utils.py", line 26, in <lambda>
    current_user = LocalProxy(lambda: _get_user())
  File "C:\Users\user\anaconda3\lib\site-packages\flask_login\utils.py", line 346, in _get_user
    current_app.login_manager._load_user()
  File "C:\Users\user\anaconda3\lib\site-packages\flask_login\login_manager.py", line 318, in _load_user
    user = self._user_callback(user_id)
  File "C:\Users\user\Desktop\kpasec22\app.py", line 116, in load_user
    return User.query.get(int(user_id))
  File "<string>", line 2, in get
  File "C:\Users\user\anaconda3\lib\site-packages\sqlalchemy\util\deprecations.py", line 390, in warned
    return fn(*args, **kwargs)
  File "C:\Users\user\anaconda3\lib\site-packages\sqlalchemy\orm\query.py", line 944, in get
    return self._get_impl(ident, loading.load_on_pk_identity)
  File "C:\Users\user\anaconda3\lib\site-packages\sqlalchemy\orm\query.py", line 948, in _get_impl
    return self.session._get_impl(
  File "C:\Users\user\anaconda3\lib\site-packages\sqlalchemy\orm\session.py", line 2839, in _get_impl
    return db_load_fn(
  File "C:\Users\user\anaconda3\lib\site-packages\sqlalchemy\orm\loading.py", line 557, in load_on_pk_identity
    session.execute(
  File "C:\Users\user\anaconda3\lib\site-packages\sqlalchemy\orm\session.py", line 1688, in execute
    conn = self._connection_for_bind(bind)
  File "C:\Users\user\anaconda3\lib\site-packages\sqlalchemy\orm\session.py", line 1529, in _connection_for_bind
    return self._transaction._connection_for_bind(
  File "C:\Users\user\anaconda3\lib\site-packages\sqlalchemy\orm\session.py", line 747, in _connection_for_bind
    conn = bind.connect()
  File "C:\Users\user\anaconda3\lib\site-packages\sqlalchemy\engine\base.py", line 3166, in connect
    return self._connection_cls(self, close_with_result=close_with_result)
  File "C:\Users\user\anaconda3\lib\site-packages\sqlalchemy\engine\base.py", line 96, in __init__
    else engine.raw_connection()
  File "C:\Users\user\anaconda3\lib\site-packages\sqlalchemy\engine\base.py", line 3245, in raw_connection
    return self._wrap_pool_connect(self.pool.connect, _connection)
  File "C:\Users\user\anaconda3\lib\site-packages\sqlalchemy\engine\base.py", line 3215, in _wrap_pool_connect
    Connection._handle_dbapi_exception_noconnection(
  File "C:\Users\user\anaconda3\lib\site-packages\sqlalchemy\engine\base.py", line 2069, in _handle_dbapi_exception_noconnection
    util.raise_(
  File "C:\Users\user\anaconda3\lib\site-packages\sqlalchemy\util\compat.py", line 207, in raise_
    raise exception
  File "C:\Users\user\anaconda3\lib\site-packages\sqlalchemy\engine\base.py", line 3212, in _wrap_pool_connect
    return fn()
  File "C:\Users\user\anaconda3\lib\site-packages\sqlalchemy\pool\base.py", line 307, in connect
    return _ConnectionFairy._checkout(self)
  File "C:\Users\user\anaconda3\lib\site-packages\sqlalchemy\pool\base.py", line 767, in _checkout
    fairy = _ConnectionRecord.checkout(pool)
  File "C:\Users\user\anaconda3\lib\site-packages\sqlalchemy\pool\base.py", line 430, in checkout
    rec._checkin_failed(err, _fairy_was_created=False)
  File "C:\Users\user\anaconda3\lib\site-packages\sqlalchemy\util\langhelpers.py", line 70, in __exit__
    compat.raise_(
  File "C:\Users\user\anaconda3\lib\site-packages\sqlalchemy\util\compat.py", line 207, in raise_
    raise exception
  File "C:\Users\user\anaconda3\lib\site-packages\sqlalchemy\pool\base.py", line 427, in checkout
    dbapi_connection = rec.get_connection()
  File "C:\Users\user\anaconda3\lib\site-packages\sqlalchemy\pool\base.py", line 552, in get_connection
    self.__connect()
  File "C:\Users\user\anaconda3\lib\site-packages\sqlalchemy\pool\base.py", line 611, in __connect
    pool.logger.debug("Error on connect(): %s", e)
  File "C:\Users\user\anaconda3\lib\site-packages\sqlalchemy\util\langhelpers.py", line 70, in __exit__
    compat.raise_(
  File "C:\Users\user\anaconda3\lib\site-packages\sqlalchemy\util\compat.py", line 207, in raise_
    raise exception
  File "C:\Users\user\anaconda3\lib\site-packages\sqlalchemy\pool\base.py", line 605, in __connect
    connection = pool._invoke_creator(self)
  File "C:\Users\user\anaconda3\lib\site-packages\sqlalchemy\engine\create.py", line 578, in connect
    return dialect.connect(*cargs, **cparams)
  File "C:\Users\user\anaconda3\lib\site-packages\sqlalchemy\engine\default.py", line 584, in connect
    return self.dbapi.connect(*cargs, **cparams)
  File "C:\Users\user\anaconda3\lib\site-packages\psycopg2\__init__.py", line 122, in connect
    conn = _connect(dsn, connection_factory=connection_factory, **kwasync)
sqlalchemy.exc.OperationalError: (psycopg2.OperationalError) connection to server at "ec2-44-192-245-97.compute-1.amazonaws.com" (44.192.245.97), port 5432 failed: FATAL:  password authentication failed for user "rcrcittfbiapfa"
connection to server at "ec2-44-192-245-97.compute-1.amazonaws.com" (44.192.245.97), port 5432 failed: FATAL:  no pg_hba.conf entry for host "102.176.94.123", user "rcrcittfbiapfa", database "da8kfqt02ehgca", SSL off

(Background on this error at: https://sqlalche.me/e/14/e3q8)
Exception on /accountant_dashboard [GET]
Traceback (most recent call last):
  File "C:\Users\user\anaconda3\lib\site-packages\sqlalchemy\engine\base.py", line 3212, in _wrap_pool_connect
    return fn()
  File "C:\Users\user\anaconda3\lib\site-packages\sqlalchemy\pool\base.py", line 307, in connect
    return _ConnectionFairy._checkout(self)
  File "C:\Users\user\anaconda3\lib\site-packages\sqlalchemy\pool\base.py", line 767, in _checkout
    fairy = _ConnectionRecord.checkout(pool)
  File "C:\Users\user\anaconda3\lib\site-packages\sqlalchemy\pool\base.py", line 430, in checkout
    rec._checkin_failed(err, _fairy_was_created=False)
  File "C:\Users\user\anaconda3\lib\site-packages\sqlalchemy\util\langhelpers.py", line 70, in __exit__
    compat.raise_(
  File "C:\Users\user\anaconda3\lib\site-packages\sqlalchemy\util\compat.py", line 207, in raise_
    raise exception
  File "C:\Users\user\anaconda3\lib\site-packages\sqlalchemy\pool\base.py", line 427, in checkout
    dbapi_connection = rec.get_connection()
  File "C:\Users\user\anaconda3\lib\site-packages\sqlalchemy\pool\base.py", line 552, in get_connection
    self.__connect()
  File "C:\Users\user\anaconda3\lib\site-packages\sqlalchemy\pool\base.py", line 611, in __connect
    pool.logger.debug("Error on connect(): %s", e)
  File "C:\Users\user\anaconda3\lib\site-packages\sqlalchemy\util\langhelpers.py", line 70, in __exit__
    compat.raise_(
  File "C:\Users\user\anaconda3\lib\site-packages\sqlalchemy\util\compat.py", line 207, in raise_
    raise exception
  File "C:\Users\user\anaconda3\lib\site-packages\sqlalchemy\pool\base.py", line 605, in __connect
    connection = pool._invoke_creator(self)
  File "C:\Users\user\anaconda3\lib\site-packages\sqlalchemy\engine\create.py", line 578, in connect
    return dialect.connect(*cargs, **cparams)
  File "C:\Users\user\anaconda3\lib\site-packages\sqlalchemy\engine\default.py", line 584, in connect
    return self.dbapi.connect(*cargs, **cparams)
  File "C:\Users\user\anaconda3\lib\site-packages\psycopg2\__init__.py", line 122, in connect
    conn = _connect(dsn, connection_factory=connection_factory, **kwasync)
psycopg2.OperationalError: connection to server at "ec2-44-192-245-97.compute-1.amazonaws.com" (44.192.245.97), port 5432 failed: FATAL:  password authentication failed for user "rcrcittfbiapfa"
connection to server at "ec2-44-192-245-97.compute-1.amazonaws.com" (44.192.245.97), port 5432 failed: FATAL:  no pg_hba.conf entry for host "102.176.94.123", user "rcrcittfbiapfa", database "da8kfqt02ehgca", SSL off


The above exception was the direct cause of the following exception:

Traceback (most recent call last):
  File "C:\Users\user\anaconda3\lib\site-packages\flask\app.py", line 2447, in wsgi_app
    response = self.full_dispatch_request()
  File "C:\Users\user\anaconda3\lib\site-packages\flask\app.py", line 1952, in full_dispatch_request
    rv = self.handle_user_exception(e)
  File "C:\Users\user\anaconda3\lib\site-packages\flask\app.py", line 1821, in handle_user_exception
    reraise(exc_type, exc_value, tb)
  File "C:\Users\user\anaconda3\lib\site-packages\flask\_compat.py", line 39, in reraise
    raise value
  File "C:\Users\user\anaconda3\lib\site-packages\flask\app.py", line 1950, in full_dispatch_request
    rv = self.dispatch_request()
  File "C:\Users\user\anaconda3\lib\site-packages\flask\app.py", line 1936, in dispatch_request
    return self.view_functions[rule.endpoint](**req.view_args)
  File "C:\Users\user\anaconda3\lib\site-packages\flask_login\utils.py", line 270, in decorated_view
    elif not current_user.is_authenticated:
  File "C:\Users\user\anaconda3\lib\site-packages\werkzeug\local.py", line 432, in __get__
    obj = instance._get_current_object()
  File "C:\Users\user\anaconda3\lib\site-packages\werkzeug\local.py", line 554, in _get_current_object
    return self.__local()  # type: ignore
  File "C:\Users\user\anaconda3\lib\site-packages\flask_login\utils.py", line 26, in <lambda>
    current_user = LocalProxy(lambda: _get_user())
  File "C:\Users\user\anaconda3\lib\site-packages\flask_login\utils.py", line 346, in _get_user
    current_app.login_manager._load_user()
  File "C:\Users\user\anaconda3\lib\site-packages\flask_login\login_manager.py", line 318, in _load_user
    user = self._user_callback(user_id)
  File "C:\Users\user\Desktop\kpasec22\app.py", line 116, in load_user
    return User.query.get(int(user_id))
  File "<string>", line 2, in get
  File "C:\Users\user\anaconda3\lib\site-packages\sqlalchemy\util\deprecations.py", line 390, in warned
    return fn(*args, **kwargs)
  File "C:\Users\user\anaconda3\lib\site-packages\sqlalchemy\orm\query.py", line 944, in get
    return self._get_impl(ident, loading.load_on_pk_identity)
  File "C:\Users\user\anaconda3\lib\site-packages\sqlalchemy\orm\query.py", line 948, in _get_impl
    return self.session._get_impl(
  File "C:\Users\user\anaconda3\lib\site-packages\sqlalchemy\orm\session.py", line 2839, in _get_impl
    return db_load_fn(
  File "C:\Users\user\anaconda3\lib\site-packages\sqlalchemy\orm\loading.py", line 557, in load_on_pk_identity
    session.execute(
  File "C:\Users\user\anaconda3\lib\site-packages\sqlalchemy\orm\session.py", line 1688, in execute
    conn = self._connection_for_bind(bind)
  File "C:\Users\user\anaconda3\lib\site-packages\sqlalchemy\orm\session.py", line 1529, in _connection_for_bind
    return self._transaction._connection_for_bind(
  File "C:\Users\user\anaconda3\lib\site-packages\sqlalchemy\orm\session.py", line 747, in _connection_for_bind
    conn = bind.connect()
  File "C:\Users\user\anaconda3\lib\site-packages\sqlalchemy\engine\base.py", line 3166, in connect
    return self._connection_cls(self, close_with_result=close_with_result)
  File "C:\Users\user\anaconda3\lib\site-packages\sqlalchemy\engine\base.py", line 96, in __init__
    else engine.raw_connection()
  File "C:\Users\user\anaconda3\lib\site-packages\sqlalchemy\engine\base.py", line 3245, in raw_connection
    return self._wrap_pool_connect(self.pool.connect, _connection)
  File "C:\Users\user\anaconda3\lib\site-packages\sqlalchemy\engine\base.py", line 3215, in _wrap_pool_connect
    Connection._handle_dbapi_exception_noconnection(
  File "C:\Users\user\anaconda3\lib\site-packages\sqlalchemy\engine\base.py", line 2069, in _handle_dbapi_exception_noconnection
    util.raise_(
  File "C:\Users\user\anaconda3\lib\site-packages\sqlalchemy\util\compat.py", line 207, in raise_
    raise exception
  File "C:\Users\user\anaconda3\lib\site-packages\sqlalchemy\engine\base.py", line 3212, in _wrap_pool_connect
    return fn()
  File "C:\Users\user\anaconda3\lib\site-packages\sqlalchemy\pool\base.py", line 307, in connect
    return _ConnectionFairy._checkout(self)
  File "C:\Users\user\anaconda3\lib\site-packages\sqlalchemy\pool\base.py", line 767, in _checkout
    fairy = _ConnectionRecord.checkout(pool)
  File "C:\Users\user\anaconda3\lib\site-packages\sqlalchemy\pool\base.py", line 430, in checkout
    rec._checkin_failed(err, _fairy_was_created=False)
  File "C:\Users\user\anaconda3\lib\site-packages\sqlalchemy\util\langhelpers.py", line 70, in __exit__
    compat.raise_(
  File "C:\Users\user\anaconda3\lib\site-packages\sqlalchemy\util\compat.py", line 207, in raise_
    raise exception
  File "C:\Users\user\anaconda3\lib\site-packages\sqlalchemy\pool\base.py", line 427, in checkout
    dbapi_connection = rec.get_connection()
  File "C:\Users\user\anaconda3\lib\site-packages\sqlalchemy\pool\base.py", line 552, in get_connection
    self.__connect()
  File "C:\Users\user\anaconda3\lib\site-packages\sqlalchemy\pool\base.py", line 611, in __connect
    pool.logger.debug("Error on connect(): %s", e)
  File "C:\Users\user\anaconda3\lib\site-packages\sqlalchemy\util\langhelpers.py", line 70, in __exit__
    compat.raise_(
  File "C:\Users\user\anaconda3\lib\site-packages\sqlalchemy\util\compat.py", line 207, in raise_
    raise exception
  File "C:\Users\user\anaconda3\lib\site-packages\sqlalchemy\pool\base.py", line 605, in __connect
    connection = pool._invoke_creator(self)
  File "C:\Users\user\anaconda3\lib\site-packages\sqlalchemy\engine\create.py", line 578, in connect
    return dialect.connect(*cargs, **cparams)
  File "C:\Users\user\anaconda3\lib\site-packages\sqlalchemy\engine\default.py", line 584, in connect
    return self.dbapi.connect(*cargs, **cparams)
  File "C:\Users\user\anaconda3\lib\site-packages\psycopg2\__init__.py", line 122, in connect
    conn = _connect(dsn, connection_factory=connection_factory, **kwasync)
sqlalchemy.exc.OperationalError: (psycopg2.OperationalError) connection to server at "ec2-44-192-245-97.compute-1.amazonaws.com" (44.192.245.97), port 5432 failed: FATAL:  password authentication failed for user "rcrcittfbiapfa"
connection to server at "ec2-44-192-245-97.compute-1.amazonaws.com" (44.192.245.97), port 5432 failed: FATAL:  no pg_hba.conf entry for host "102.176.94.123", user "rcrcittfbiapfa", database "da8kfqt02ehgca", SSL off

(Background on this error at: https://sqlalche.me/e/14/e3q8)
Exception on / [GET]
Traceback (most recent call last):
  File "C:\Users\user\anaconda3\lib\site-packages\sqlalchemy\engine\base.py", line 3212, in _wrap_pool_connect
    return fn()
  File "C:\Users\user\anaconda3\lib\site-packages\sqlalchemy\pool\base.py", line 307, in connect
    return _ConnectionFairy._checkout(self)
  File "C:\Users\user\anaconda3\lib\site-packages\sqlalchemy\pool\base.py", line 767, in _checkout
    fairy = _ConnectionRecord.checkout(pool)
  File "C:\Users\user\anaconda3\lib\site-packages\sqlalchemy\pool\base.py", line 430, in checkout
    rec._checkin_failed(err, _fairy_was_created=False)
  File "C:\Users\user\anaconda3\lib\site-packages\sqlalchemy\util\langhelpers.py", line 70, in __exit__
    compat.raise_(
  File "C:\Users\user\anaconda3\lib\site-packages\sqlalchemy\util\compat.py", line 207, in raise_
    raise exception
  File "C:\Users\user\anaconda3\lib\site-packages\sqlalchemy\pool\base.py", line 427, in checkout
    dbapi_connection = rec.get_connection()
  File "C:\Users\user\anaconda3\lib\site-packages\sqlalchemy\pool\base.py", line 552, in get_connection
    self.__connect()
  File "C:\Users\user\anaconda3\lib\site-packages\sqlalchemy\pool\base.py", line 611, in __connect
    pool.logger.debug("Error on connect(): %s", e)
  File "C:\Users\user\anaconda3\lib\site-packages\sqlalchemy\util\langhelpers.py", line 70, in __exit__
    compat.raise_(
  File "C:\Users\user\anaconda3\lib\site-packages\sqlalchemy\util\compat.py", line 207, in raise_
    raise exception
  File "C:\Users\user\anaconda3\lib\site-packages\sqlalchemy\pool\base.py", line 605, in __connect
    connection = pool._invoke_creator(self)
  File "C:\Users\user\anaconda3\lib\site-packages\sqlalchemy\engine\create.py", line 578, in connect
    return dialect.connect(*cargs, **cparams)
  File "C:\Users\user\anaconda3\lib\site-packages\sqlalchemy\engine\default.py", line 584, in connect
    return self.dbapi.connect(*cargs, **cparams)
  File "C:\Users\user\anaconda3\lib\site-packages\psycopg2\__init__.py", line 122, in connect
    conn = _connect(dsn, connection_factory=connection_factory, **kwasync)
psycopg2.OperationalError: connection to server at "ec2-44-192-245-97.compute-1.amazonaws.com" (44.192.245.97), port 5432 failed: FATAL:  password authentication failed for user "rcrcittfbiapfa"
connection to server at "ec2-44-192-245-97.compute-1.amazonaws.com" (44.192.245.97), port 5432 failed: FATAL:  no pg_hba.conf entry for host "102.176.94.145", user "rcrcittfbiapfa", database "da8kfqt02ehgca", SSL off


The above exception was the direct cause of the following exception:

Traceback (most recent call last):
  File "C:\Users\user\anaconda3\lib\site-packages\flask\app.py", line 2447, in wsgi_app
    response = self.full_dispatch_request()
  File "C:\Users\user\anaconda3\lib\site-packages\flask\app.py", line 1952, in full_dispatch_request
    rv = self.handle_user_exception(e)
  File "C:\Users\user\anaconda3\lib\site-packages\flask\app.py", line 1821, in handle_user_exception
    reraise(exc_type, exc_value, tb)
  File "C:\Users\user\anaconda3\lib\site-packages\flask\_compat.py", line 39, in reraise
    raise value
  File "C:\Users\user\anaconda3\lib\site-packages\flask\app.py", line 1950, in full_dispatch_request
    rv = self.dispatch_request()
  File "C:\Users\user\anaconda3\lib\site-packages\flask\app.py", line 1936, in dispatch_request
    return self.view_functions[rule.endpoint](**req.view_args)
  File "C:\Users\user\Desktop\kpasec22\app.py", line 129, in home
    return render_template("homepage1.html")
  File "C:\Users\user\anaconda3\lib\site-packages\flask\templating.py", line 136, in render_template
    ctx.app.update_template_context(context)
  File "C:\Users\user\anaconda3\lib\site-packages\flask\app.py", line 838, in update_template_context
    context.update(func())
  File "C:\Users\user\anaconda3\lib\site-packages\flask_login\utils.py", line 379, in _user_context_processor
    return dict(current_user=_get_user())
  File "C:\Users\user\anaconda3\lib\site-packages\flask_login\utils.py", line 346, in _get_user
    current_app.login_manager._load_user()
  File "C:\Users\user\anaconda3\lib\site-packages\flask_login\login_manager.py", line 318, in _load_user
    user = self._user_callback(user_id)
  File "C:\Users\user\Desktop\kpasec22\app.py", line 116, in load_user
    return User.query.get(int(user_id))
  File "<string>", line 2, in get
  File "C:\Users\user\anaconda3\lib\site-packages\sqlalchemy\util\deprecations.py", line 390, in warned
    return fn(*args, **kwargs)
  File "C:\Users\user\anaconda3\lib\site-packages\sqlalchemy\orm\query.py", line 944, in get
    return self._get_impl(ident, loading.load_on_pk_identity)
  File "C:\Users\user\anaconda3\lib\site-packages\sqlalchemy\orm\query.py", line 948, in _get_impl
    return self.session._get_impl(
  File "C:\Users\user\anaconda3\lib\site-packages\sqlalchemy\orm\session.py", line 2839, in _get_impl
    return db_load_fn(
  File "C:\Users\user\anaconda3\lib\site-packages\sqlalchemy\orm\loading.py", line 557, in load_on_pk_identity
    session.execute(
  File "C:\Users\user\anaconda3\lib\site-packages\sqlalchemy\orm\session.py", line 1688, in execute
    conn = self._connection_for_bind(bind)
  File "C:\Users\user\anaconda3\lib\site-packages\sqlalchemy\orm\session.py", line 1529, in _connection_for_bind
    return self._transaction._connection_for_bind(
  File "C:\Users\user\anaconda3\lib\site-packages\sqlalchemy\orm\session.py", line 747, in _connection_for_bind
    conn = bind.connect()
  File "C:\Users\user\anaconda3\lib\site-packages\sqlalchemy\engine\base.py", line 3166, in connect
    return self._connection_cls(self, close_with_result=close_with_result)
  File "C:\Users\user\anaconda3\lib\site-packages\sqlalchemy\engine\base.py", line 96, in __init__
    else engine.raw_connection()
  File "C:\Users\user\anaconda3\lib\site-packages\sqlalchemy\engine\base.py", line 3245, in raw_connection
    return self._wrap_pool_connect(self.pool.connect, _connection)
  File "C:\Users\user\anaconda3\lib\site-packages\sqlalchemy\engine\base.py", line 3215, in _wrap_pool_connect
    Connection._handle_dbapi_exception_noconnection(
  File "C:\Users\user\anaconda3\lib\site-packages\sqlalchemy\engine\base.py", line 2069, in _handle_dbapi_exception_noconnection
    util.raise_(
  File "C:\Users\user\anaconda3\lib\site-packages\sqlalchemy\util\compat.py", line 207, in raise_
    raise exception
  File "C:\Users\user\anaconda3\lib\site-packages\sqlalchemy\engine\base.py", line 3212, in _wrap_pool_connect
    return fn()
  File "C:\Users\user\anaconda3\lib\site-packages\sqlalchemy\pool\base.py", line 307, in connect
    return _ConnectionFairy._checkout(self)
  File "C:\Users\user\anaconda3\lib\site-packages\sqlalchemy\pool\base.py", line 767, in _checkout
    fairy = _ConnectionRecord.checkout(pool)
  File "C:\Users\user\anaconda3\lib\site-packages\sqlalchemy\pool\base.py", line 430, in checkout
    rec._checkin_failed(err, _fairy_was_created=False)
  File "C:\Users\user\anaconda3\lib\site-packages\sqlalchemy\util\langhelpers.py", line 70, in __exit__
    compat.raise_(
  File "C:\Users\user\anaconda3\lib\site-packages\sqlalchemy\util\compat.py", line 207, in raise_
    raise exception
  File "C:\Users\user\anaconda3\lib\site-packages\sqlalchemy\pool\base.py", line 427, in checkout
    dbapi_connection = rec.get_connection()
  File "C:\Users\user\anaconda3\lib\site-packages\sqlalchemy\pool\base.py", line 552, in get_connection
    self.__connect()
  File "C:\Users\user\anaconda3\lib\site-packages\sqlalchemy\pool\base.py", line 611, in __connect
    pool.logger.debug("Error on connect(): %s", e)
  File "C:\Users\user\anaconda3\lib\site-packages\sqlalchemy\util\langhelpers.py", line 70, in __exit__
    compat.raise_(
  File "C:\Users\user\anaconda3\lib\site-packages\sqlalchemy\util\compat.py", line 207, in raise_
    raise exception
  File "C:\Users\user\anaconda3\lib\site-packages\sqlalchemy\pool\base.py", line 605, in __connect
    connection = pool._invoke_creator(self)
  File "C:\Users\user\anaconda3\lib\site-packages\sqlalchemy\engine\create.py", line 578, in connect
    return dialect.connect(*cargs, **cparams)
  File "C:\Users\user\anaconda3\lib\site-packages\sqlalchemy\engine\default.py", line 584, in connect
    return self.dbapi.connect(*cargs, **cparams)
  File "C:\Users\user\anaconda3\lib\site-packages\psycopg2\__init__.py", line 122, in connect
    conn = _connect(dsn, connection_factory=connection_factory, **kwasync)
sqlalchemy.exc.OperationalError: (psycopg2.OperationalError) connection to server at "ec2-44-192-245-97.compute-1.amazonaws.com" (44.192.245.97), port 5432 failed: FATAL:  password authentication failed for user "rcrcittfbiapfa"
connection to server at "ec2-44-192-245-97.compute-1.amazonaws.com" (44.192.245.97), port 5432 failed: FATAL:  no pg_hba.conf entry for host "102.176.94.145", user "rcrcittfbiapfa", database "da8kfqt02ehgca", SSL off

(Background on this error at: https://sqlalche.me/e/14/e3q8)
Exception on / [GET]
Traceback (most recent call last):
  File "C:\Users\user\anaconda3\lib\site-packages\sqlalchemy\engine\base.py", line 3212, in _wrap_pool_connect
    return fn()
  File "C:\Users\user\anaconda3\lib\site-packages\sqlalchemy\pool\base.py", line 307, in connect
    return _ConnectionFairy._checkout(self)
  File "C:\Users\user\anaconda3\lib\site-packages\sqlalchemy\pool\base.py", line 767, in _checkout
    fairy = _ConnectionRecord.checkout(pool)
  File "C:\Users\user\anaconda3\lib\site-packages\sqlalchemy\pool\base.py", line 430, in checkout
    rec._checkin_failed(err, _fairy_was_created=False)
  File "C:\Users\user\anaconda3\lib\site-packages\sqlalchemy\util\langhelpers.py", line 70, in __exit__
    compat.raise_(
  File "C:\Users\user\anaconda3\lib\site-packages\sqlalchemy\util\compat.py", line 207, in raise_
    raise exception
  File "C:\Users\user\anaconda3\lib\site-packages\sqlalchemy\pool\base.py", line 427, in checkout
    dbapi_connection = rec.get_connection()
  File "C:\Users\user\anaconda3\lib\site-packages\sqlalchemy\pool\base.py", line 552, in get_connection
    self.__connect()
  File "C:\Users\user\anaconda3\lib\site-packages\sqlalchemy\pool\base.py", line 611, in __connect
    pool.logger.debug("Error on connect(): %s", e)
  File "C:\Users\user\anaconda3\lib\site-packages\sqlalchemy\util\langhelpers.py", line 70, in __exit__
    compat.raise_(
  File "C:\Users\user\anaconda3\lib\site-packages\sqlalchemy\util\compat.py", line 207, in raise_
    raise exception
  File "C:\Users\user\anaconda3\lib\site-packages\sqlalchemy\pool\base.py", line 605, in __connect
    connection = pool._invoke_creator(self)
  File "C:\Users\user\anaconda3\lib\site-packages\sqlalchemy\engine\create.py", line 578, in connect
    return dialect.connect(*cargs, **cparams)
  File "C:\Users\user\anaconda3\lib\site-packages\sqlalchemy\engine\default.py", line 584, in connect
    return self.dbapi.connect(*cargs, **cparams)
  File "C:\Users\user\anaconda3\lib\site-packages\psycopg2\__init__.py", line 122, in connect
    conn = _connect(dsn, connection_factory=connection_factory, **kwasync)
psycopg2.OperationalError: could not translate host name "ec2-44-192-245-97.compute-1.amazonaws.com" to address: Unknown host


The above exception was the direct cause of the following exception:

Traceback (most recent call last):
  File "C:\Users\user\anaconda3\lib\site-packages\flask\app.py", line 2447, in wsgi_app
    response = self.full_dispatch_request()
  File "C:\Users\user\anaconda3\lib\site-packages\flask\app.py", line 1952, in full_dispatch_request
    rv = self.handle_user_exception(e)
  File "C:\Users\user\anaconda3\lib\site-packages\flask\app.py", line 1821, in handle_user_exception
    reraise(exc_type, exc_value, tb)
  File "C:\Users\user\anaconda3\lib\site-packages\flask\_compat.py", line 39, in reraise
    raise value
  File "C:\Users\user\anaconda3\lib\site-packages\flask\app.py", line 1950, in full_dispatch_request
    rv = self.dispatch_request()
  File "C:\Users\user\anaconda3\lib\site-packages\flask\app.py", line 1936, in dispatch_request
    return self.view_functions[rule.endpoint](**req.view_args)
  File "C:\Users\user\Desktop\kpasec22\app.py", line 129, in home
    return render_template("homepage1.html")
  File "C:\Users\user\anaconda3\lib\site-packages\flask\templating.py", line 136, in render_template
    ctx.app.update_template_context(context)
  File "C:\Users\user\anaconda3\lib\site-packages\flask\app.py", line 838, in update_template_context
    context.update(func())
  File "C:\Users\user\anaconda3\lib\site-packages\flask_login\utils.py", line 379, in _user_context_processor
    return dict(current_user=_get_user())
  File "C:\Users\user\anaconda3\lib\site-packages\flask_login\utils.py", line 346, in _get_user
    current_app.login_manager._load_user()
  File "C:\Users\user\anaconda3\lib\site-packages\flask_login\login_manager.py", line 318, in _load_user
    user = self._user_callback(user_id)
  File "C:\Users\user\Desktop\kpasec22\app.py", line 116, in load_user
    return User.query.get(int(user_id))
  File "<string>", line 2, in get
  File "C:\Users\user\anaconda3\lib\site-packages\sqlalchemy\util\deprecations.py", line 390, in warned
    return fn(*args, **kwargs)
  File "C:\Users\user\anaconda3\lib\site-packages\sqlalchemy\orm\query.py", line 944, in get
    return self._get_impl(ident, loading.load_on_pk_identity)
  File "C:\Users\user\anaconda3\lib\site-packages\sqlalchemy\orm\query.py", line 948, in _get_impl
    return self.session._get_impl(
  File "C:\Users\user\anaconda3\lib\site-packages\sqlalchemy\orm\session.py", line 2839, in _get_impl
    return db_load_fn(
  File "C:\Users\user\anaconda3\lib\site-packages\sqlalchemy\orm\loading.py", line 557, in load_on_pk_identity
    session.execute(
  File "C:\Users\user\anaconda3\lib\site-packages\sqlalchemy\orm\session.py", line 1688, in execute
    conn = self._connection_for_bind(bind)
  File "C:\Users\user\anaconda3\lib\site-packages\sqlalchemy\orm\session.py", line 1529, in _connection_for_bind
    return self._transaction._connection_for_bind(
  File "C:\Users\user\anaconda3\lib\site-packages\sqlalchemy\orm\session.py", line 747, in _connection_for_bind
    conn = bind.connect()
  File "C:\Users\user\anaconda3\lib\site-packages\sqlalchemy\engine\base.py", line 3166, in connect
    return self._connection_cls(self, close_with_result=close_with_result)
  File "C:\Users\user\anaconda3\lib\site-packages\sqlalchemy\engine\base.py", line 96, in __init__
    else engine.raw_connection()
  File "C:\Users\user\anaconda3\lib\site-packages\sqlalchemy\engine\base.py", line 3245, in raw_connection
    return self._wrap_pool_connect(self.pool.connect, _connection)
  File "C:\Users\user\anaconda3\lib\site-packages\sqlalchemy\engine\base.py", line 3215, in _wrap_pool_connect
    Connection._handle_dbapi_exception_noconnection(
  File "C:\Users\user\anaconda3\lib\site-packages\sqlalchemy\engine\base.py", line 2069, in _handle_dbapi_exception_noconnection
    util.raise_(
  File "C:\Users\user\anaconda3\lib\site-packages\sqlalchemy\util\compat.py", line 207, in raise_
    raise exception
  File "C:\Users\user\anaconda3\lib\site-packages\sqlalchemy\engine\base.py", line 3212, in _wrap_pool_connect
    return fn()
  File "C:\Users\user\anaconda3\lib\site-packages\sqlalchemy\pool\base.py", line 307, in connect
    return _ConnectionFairy._checkout(self)
  File "C:\Users\user\anaconda3\lib\site-packages\sqlalchemy\pool\base.py", line 767, in _checkout
    fairy = _ConnectionRecord.checkout(pool)
  File "C:\Users\user\anaconda3\lib\site-packages\sqlalchemy\pool\base.py", line 430, in checkout
    rec._checkin_failed(err, _fairy_was_created=False)
  File "C:\Users\user\anaconda3\lib\site-packages\sqlalchemy\util\langhelpers.py", line 70, in __exit__
    compat.raise_(
  File "C:\Users\user\anaconda3\lib\site-packages\sqlalchemy\util\compat.py", line 207, in raise_
    raise exception
  File "C:\Users\user\anaconda3\lib\site-packages\sqlalchemy\pool\base.py", line 427, in checkout
    dbapi_connection = rec.get_connection()
  File "C:\Users\user\anaconda3\lib\site-packages\sqlalchemy\pool\base.py", line 552, in get_connection
    self.__connect()
  File "C:\Users\user\anaconda3\lib\site-packages\sqlalchemy\pool\base.py", line 611, in __connect
    pool.logger.debug("Error on connect(): %s", e)
  File "C:\Users\user\anaconda3\lib\site-packages\sqlalchemy\util\langhelpers.py", line 70, in __exit__
    compat.raise_(
  File "C:\Users\user\anaconda3\lib\site-packages\sqlalchemy\util\compat.py", line 207, in raise_
    raise exception
  File "C:\Users\user\anaconda3\lib\site-packages\sqlalchemy\pool\base.py", line 605, in __connect
    connection = pool._invoke_creator(self)
  File "C:\Users\user\anaconda3\lib\site-packages\sqlalchemy\engine\create.py", line 578, in connect
    return dialect.connect(*cargs, **cparams)
  File "C:\Users\user\anaconda3\lib\site-packages\sqlalchemy\engine\default.py", line 584, in connect
    return self.dbapi.connect(*cargs, **cparams)
  File "C:\Users\user\anaconda3\lib\site-packages\psycopg2\__init__.py", line 122, in connect
    conn = _connect(dsn, connection_factory=connection_factory, **kwasync)
sqlalchemy.exc.OperationalError: (psycopg2.OperationalError) could not translate host name "ec2-44-192-245-97.compute-1.amazonaws.com" to address: Unknown host

(Background on this error at: https://sqlalche.me/e/14/e3q8)
Exception on / [GET]
Traceback (most recent call last):
  File "C:\Users\user\anaconda3\lib\site-packages\sqlalchemy\engine\base.py", line 1771, in _execute_context
    self.dialect.do_execute(
  File "C:\Users\user\anaconda3\lib\site-packages\sqlalchemy\engine\default.py", line 717, in do_execute
    cursor.execute(statement, parameters)
sqlite3.OperationalError: no such table: user

The above exception was the direct cause of the following exception:

Traceback (most recent call last):
  File "C:\Users\user\anaconda3\lib\site-packages\flask\app.py", line 2447, in wsgi_app
    response = self.full_dispatch_request()
  File "C:\Users\user\anaconda3\lib\site-packages\flask\app.py", line 1952, in full_dispatch_request
    rv = self.handle_user_exception(e)
  File "C:\Users\user\anaconda3\lib\site-packages\flask\app.py", line 1821, in handle_user_exception
    reraise(exc_type, exc_value, tb)
  File "C:\Users\user\anaconda3\lib\site-packages\flask\_compat.py", line 39, in reraise
    raise value
  File "C:\Users\user\anaconda3\lib\site-packages\flask\app.py", line 1950, in full_dispatch_request
    rv = self.dispatch_request()
  File "C:\Users\user\anaconda3\lib\site-packages\flask\app.py", line 1936, in dispatch_request
    return self.view_functions[rule.endpoint](**req.view_args)
  File "C:\Users\user\Desktop\kpasec22\app.py", line 129, in home
    return render_template("homepage1.html")
  File "C:\Users\user\anaconda3\lib\site-packages\flask\templating.py", line 136, in render_template
    ctx.app.update_template_context(context)
  File "C:\Users\user\anaconda3\lib\site-packages\flask\app.py", line 838, in update_template_context
    context.update(func())
  File "C:\Users\user\anaconda3\lib\site-packages\flask_login\utils.py", line 379, in _user_context_processor
    return dict(current_user=_get_user())
  File "C:\Users\user\anaconda3\lib\site-packages\flask_login\utils.py", line 346, in _get_user
    current_app.login_manager._load_user()
  File "C:\Users\user\anaconda3\lib\site-packages\flask_login\login_manager.py", line 318, in _load_user
    user = self._user_callback(user_id)
  File "C:\Users\user\Desktop\kpasec22\app.py", line 116, in load_user
    return User.query.get(int(user_id))
  File "<string>", line 2, in get
  File "C:\Users\user\anaconda3\lib\site-packages\sqlalchemy\util\deprecations.py", line 390, in warned
    return fn(*args, **kwargs)
  File "C:\Users\user\anaconda3\lib\site-packages\sqlalchemy\orm\query.py", line 944, in get
    return self._get_impl(ident, loading.load_on_pk_identity)
  File "C:\Users\user\anaconda3\lib\site-packages\sqlalchemy\orm\query.py", line 948, in _get_impl
    return self.session._get_impl(
  File "C:\Users\user\anaconda3\lib\site-packages\sqlalchemy\orm\session.py", line 2839, in _get_impl
    return db_load_fn(
  File "C:\Users\user\anaconda3\lib\site-packages\sqlalchemy\orm\loading.py", line 557, in load_on_pk_identity
    session.execute(
  File "C:\Users\user\anaconda3\lib\site-packages\sqlalchemy\orm\session.py", line 1689, in execute
    result = conn._execute_20(statement, params or {}, execution_options)
  File "C:\Users\user\anaconda3\lib\site-packages\sqlalchemy\engine\base.py", line 1583, in _execute_20
    return meth(self, args_10style, kwargs_10style, execution_options)
  File "C:\Users\user\anaconda3\lib\site-packages\sqlalchemy\sql\elements.py", line 323, in _execute_on_connection
    return connection._execute_clauseelement(
  File "C:\Users\user\anaconda3\lib\site-packages\sqlalchemy\engine\base.py", line 1452, in _execute_clauseelement
    ret = self._execute_context(
  File "C:\Users\user\anaconda3\lib\site-packages\sqlalchemy\engine\base.py", line 1814, in _execute_context
    self._handle_dbapi_exception(
  File "C:\Users\user\anaconda3\lib\site-packages\sqlalchemy\engine\base.py", line 1995, in _handle_dbapi_exception
    util.raise_(
  File "C:\Users\user\anaconda3\lib\site-packages\sqlalchemy\util\compat.py", line 207, in raise_
    raise exception
  File "C:\Users\user\anaconda3\lib\site-packages\sqlalchemy\engine\base.py", line 1771, in _execute_context
    self.dialect.do_execute(
  File "C:\Users\user\anaconda3\lib\site-packages\sqlalchemy\engine\default.py", line 717, in do_execute
    cursor.execute(statement, parameters)
sqlalchemy.exc.OperationalError: (sqlite3.OperationalError) no such table: user
[SQL: SELECT user.id AS user_id, user.date AS user_date, user.username AS user_username, user.email AS user_email, user.password AS user_password, user.is_admin AS user_is_admin, user.function AS user_function, user.approval AS user_approval 
FROM user 
WHERE user.id = ?]
[parameters: (1,)]
(Background on this error at: https://sqlalche.me/e/14/e3q8)
Exception on /accountant_dashboard [POST]
Traceback (most recent call last):
  File "C:\Users\user\anaconda3\lib\site-packages\sqlalchemy\engine\base.py", line 1771, in _execute_context
    self.dialect.do_execute(
  File "C:\Users\user\anaconda3\lib\site-packages\sqlalchemy\engine\default.py", line 717, in do_execute
    cursor.execute(statement, parameters)
sqlite3.OperationalError: no such table: user

The above exception was the direct cause of the following exception:

Traceback (most recent call last):
  File "C:\Users\user\anaconda3\lib\site-packages\flask\app.py", line 2447, in wsgi_app
    response = self.full_dispatch_request()
  File "C:\Users\user\anaconda3\lib\site-packages\flask\app.py", line 1952, in full_dispatch_request
    rv = self.handle_user_exception(e)
  File "C:\Users\user\anaconda3\lib\site-packages\flask\app.py", line 1821, in handle_user_exception
    reraise(exc_type, exc_value, tb)
  File "C:\Users\user\anaconda3\lib\site-packages\flask\_compat.py", line 39, in reraise
    raise value
  File "C:\Users\user\anaconda3\lib\site-packages\flask\app.py", line 1950, in full_dispatch_request
    rv = self.dispatch_request()
  File "C:\Users\user\anaconda3\lib\site-packages\flask\app.py", line 1936, in dispatch_request
    return self.view_functions[rule.endpoint](**req.view_args)
  File "C:\Users\user\anaconda3\lib\site-packages\flask_login\utils.py", line 270, in decorated_view
    elif not current_user.is_authenticated:
  File "C:\Users\user\anaconda3\lib\site-packages\werkzeug\local.py", line 432, in __get__
    obj = instance._get_current_object()
  File "C:\Users\user\anaconda3\lib\site-packages\werkzeug\local.py", line 554, in _get_current_object
    return self.__local()  # type: ignore
  File "C:\Users\user\anaconda3\lib\site-packages\flask_login\utils.py", line 26, in <lambda>
    current_user = LocalProxy(lambda: _get_user())
  File "C:\Users\user\anaconda3\lib\site-packages\flask_login\utils.py", line 346, in _get_user
    current_app.login_manager._load_user()
  File "C:\Users\user\anaconda3\lib\site-packages\flask_login\login_manager.py", line 318, in _load_user
    user = self._user_callback(user_id)
  File "C:\Users\user\Desktop\kpasec22\app.py", line 116, in load_user
    return User.query.get(int(user_id))
  File "<string>", line 2, in get
  File "C:\Users\user\anaconda3\lib\site-packages\sqlalchemy\util\deprecations.py", line 390, in warned
    return fn(*args, **kwargs)
  File "C:\Users\user\anaconda3\lib\site-packages\sqlalchemy\orm\query.py", line 944, in get
    return self._get_impl(ident, loading.load_on_pk_identity)
  File "C:\Users\user\anaconda3\lib\site-packages\sqlalchemy\orm\query.py", line 948, in _get_impl
    return self.session._get_impl(
  File "C:\Users\user\anaconda3\lib\site-packages\sqlalchemy\orm\session.py", line 2839, in _get_impl
    return db_load_fn(
  File "C:\Users\user\anaconda3\lib\site-packages\sqlalchemy\orm\loading.py", line 557, in load_on_pk_identity
    session.execute(
  File "C:\Users\user\anaconda3\lib\site-packages\sqlalchemy\orm\session.py", line 1689, in execute
    result = conn._execute_20(statement, params or {}, execution_options)
  File "C:\Users\user\anaconda3\lib\site-packages\sqlalchemy\engine\base.py", line 1583, in _execute_20
    return meth(self, args_10style, kwargs_10style, execution_options)
  File "C:\Users\user\anaconda3\lib\site-packages\sqlalchemy\sql\elements.py", line 323, in _execute_on_connection
    return connection._execute_clauseelement(
  File "C:\Users\user\anaconda3\lib\site-packages\sqlalchemy\engine\base.py", line 1452, in _execute_clauseelement
    ret = self._execute_context(
  File "C:\Users\user\anaconda3\lib\site-packages\sqlalchemy\engine\base.py", line 1814, in _execute_context
    self._handle_dbapi_exception(
  File "C:\Users\user\anaconda3\lib\site-packages\sqlalchemy\engine\base.py", line 1995, in _handle_dbapi_exception
    util.raise_(
  File "C:\Users\user\anaconda3\lib\site-packages\sqlalchemy\util\compat.py", line 207, in raise_
    raise exception
  File "C:\Users\user\anaconda3\lib\site-packages\sqlalchemy\engine\base.py", line 1771, in _execute_context
    self.dialect.do_execute(
  File "C:\Users\user\anaconda3\lib\site-packages\sqlalchemy\engine\default.py", line 717, in do_execute
    cursor.execute(statement, parameters)
sqlalchemy.exc.OperationalError: (sqlite3.OperationalError) no such table: user
[SQL: SELECT user.id AS user_id, user.date AS user_date, user.username AS user_username, user.email AS user_email, user.password AS user_password, user.is_admin AS user_is_admin, user.function AS user_function, user.approval AS user_approval 
FROM user 
WHERE user.id = ?]
[parameters: (1,)]
(Background on this error at: https://sqlalche.me/e/14/e3q8)
Exception on /accountant_dashboard [GET]
Traceback (most recent call last):
  File "C:\Users\user\.virtualenvs\kpasec22-pTKp68im\lib\site-packages\sqlalchemy\util\_collections.py", line 1008, in __call__
    return self.registry[key]
KeyError: <greenlet.greenlet object at 0x000002B3EEB09A90 (otid=0x000002B3EEB0AA40) current active started main>

During handling of the above exception, another exception occurred:

Traceback (most recent call last):
  File "C:\Users\user\.virtualenvs\kpasec22-pTKp68im\lib\site-packages\flask\app.py", line 2073, in wsgi_app
    response = self.full_dispatch_request()
  File "C:\Users\user\.virtualenvs\kpasec22-pTKp68im\lib\site-packages\flask\app.py", line 1518, in full_dispatch_request
    rv = self.handle_user_exception(e)
  File "C:\Users\user\.virtualenvs\kpasec22-pTKp68im\lib\site-packages\flask\app.py", line 1516, in full_dispatch_request
    rv = self.dispatch_request()
  File "C:\Users\user\.virtualenvs\kpasec22-pTKp68im\lib\site-packages\flask\app.py", line 1502, in dispatch_request
    return self.ensure_sync(self.view_functions[rule.endpoint])(**req.view_args)
  File "C:\Users\user\.virtualenvs\kpasec22-pTKp68im\lib\site-packages\flask_login\utils.py", line 270, in decorated_view
    elif not current_user.is_authenticated:
  File "C:\Users\user\.virtualenvs\kpasec22-pTKp68im\lib\site-packages\werkzeug\local.py", line 436, in __get__
    obj = instance._get_current_object()
  File "C:\Users\user\.virtualenvs\kpasec22-pTKp68im\lib\site-packages\werkzeug\local.py", line 565, in _get_current_object
    return self.__local()  # type: ignore
  File "C:\Users\user\.virtualenvs\kpasec22-pTKp68im\lib\site-packages\flask_login\utils.py", line 26, in <lambda>
    current_user = LocalProxy(lambda: _get_user())
  File "C:\Users\user\.virtualenvs\kpasec22-pTKp68im\lib\site-packages\flask_login\utils.py", line 346, in _get_user
    current_app.login_manager._load_user()
  File "C:\Users\user\.virtualenvs\kpasec22-pTKp68im\lib\site-packages\flask_login\login_manager.py", line 318, in _load_user
    user = self._user_callback(user_id)
  File "C:\Users\user\Desktop\kpasec22\app.py", line 132, in load_user
    return User.query.get(int(user_id))
  File "C:\Users\user\.virtualenvs\kpasec22-pTKp68im\lib\site-packages\flask_sqlalchemy\__init__.py", line 552, in __get__
    return type.query_class(mapper, session=self.sa.session())
  File "C:\Users\user\.virtualenvs\kpasec22-pTKp68im\lib\site-packages\sqlalchemy\orm\scoping.py", line 47, in __call__
    sess = self.registry()
  File "C:\Users\user\.virtualenvs\kpasec22-pTKp68im\lib\site-packages\sqlalchemy\util\_collections.py", line 1010, in __call__
    return self.registry.setdefault(key, self.createfunc())
  File "C:\Users\user\.virtualenvs\kpasec22-pTKp68im\lib\site-packages\sqlalchemy\orm\session.py", line 4205, in __call__
    return self.class_(**local_kw)
  File "C:\Users\user\.virtualenvs\kpasec22-pTKp68im\lib\site-packages\flask_sqlalchemy\__init__.py", line 176, in __init__
    bind = options.pop('bind', None) or db.engine
  File "C:\Users\user\.virtualenvs\kpasec22-pTKp68im\lib\site-packages\flask_sqlalchemy\__init__.py", line 998, in engine
    return self.get_engine()
  File "C:\Users\user\.virtualenvs\kpasec22-pTKp68im\lib\site-packages\flask_sqlalchemy\__init__.py", line 1017, in get_engine
    return connector.get_engine()
  File "C:\Users\user\.virtualenvs\kpasec22-pTKp68im\lib\site-packages\flask_sqlalchemy\__init__.py", line 594, in get_engine
    self._engine = rv = self._sa.create_engine(sa_url, options)
  File "C:\Users\user\.virtualenvs\kpasec22-pTKp68im\lib\site-packages\flask_sqlalchemy\__init__.py", line 1027, in create_engine
    return sqlalchemy.create_engine(sa_url, **engine_opts)
  File "<string>", line 2, in create_engine
  File "C:\Users\user\.virtualenvs\kpasec22-pTKp68im\lib\site-packages\sqlalchemy\util\deprecations.py", line 309, in warned
    return fn(*args, **kwargs)
  File "C:\Users\user\.virtualenvs\kpasec22-pTKp68im\lib\site-packages\sqlalchemy\engine\create.py", line 560, in create_engine
    dbapi = dialect_cls.dbapi(**dbapi_args)
  File "C:\Users\user\.virtualenvs\kpasec22-pTKp68im\lib\site-packages\sqlalchemy\dialects\postgresql\psycopg2.py", line 782, in dbapi
    import psycopg2
ModuleNotFoundError: No module named 'psycopg2'
Exception on /accountant_dashboard [GET]
Traceback (most recent call last):
  File "C:\Users\user\.virtualenvs\kpasec22-pTKp68im\lib\site-packages\sqlalchemy\engine\base.py", line 3256, in _wrap_pool_connect
    return fn()
  File "C:\Users\user\.virtualenvs\kpasec22-pTKp68im\lib\site-packages\sqlalchemy\pool\base.py", line 310, in connect
    return _ConnectionFairy._checkout(self)
  File "C:\Users\user\.virtualenvs\kpasec22-pTKp68im\lib\site-packages\sqlalchemy\pool\base.py", line 868, in _checkout
    fairy = _ConnectionRecord.checkout(pool)
  File "C:\Users\user\.virtualenvs\kpasec22-pTKp68im\lib\site-packages\sqlalchemy\pool\base.py", line 476, in checkout
    rec = pool._do_get()
  File "C:\Users\user\.virtualenvs\kpasec22-pTKp68im\lib\site-packages\sqlalchemy\pool\impl.py", line 146, in _do_get
    self._dec_overflow()
  File "C:\Users\user\.virtualenvs\kpasec22-pTKp68im\lib\site-packages\sqlalchemy\util\langhelpers.py", line 70, in __exit__
    compat.raise_(
  File "C:\Users\user\.virtualenvs\kpasec22-pTKp68im\lib\site-packages\sqlalchemy\util\compat.py", line 207, in raise_
    raise exception
  File "C:\Users\user\.virtualenvs\kpasec22-pTKp68im\lib\site-packages\sqlalchemy\pool\impl.py", line 143, in _do_get
    return self._create_connection()
  File "C:\Users\user\.virtualenvs\kpasec22-pTKp68im\lib\site-packages\sqlalchemy\pool\base.py", line 256, in _create_connection
    return _ConnectionRecord(self)
  File "C:\Users\user\.virtualenvs\kpasec22-pTKp68im\lib\site-packages\sqlalchemy\pool\base.py", line 371, in __init__
    self.__connect()
  File "C:\Users\user\.virtualenvs\kpasec22-pTKp68im\lib\site-packages\sqlalchemy\pool\base.py", line 666, in __connect
    pool.logger.debug("Error on connect(): %s", e)
  File "C:\Users\user\.virtualenvs\kpasec22-pTKp68im\lib\site-packages\sqlalchemy\util\langhelpers.py", line 70, in __exit__
    compat.raise_(
  File "C:\Users\user\.virtualenvs\kpasec22-pTKp68im\lib\site-packages\sqlalchemy\util\compat.py", line 207, in raise_
    raise exception
  File "C:\Users\user\.virtualenvs\kpasec22-pTKp68im\lib\site-packages\sqlalchemy\pool\base.py", line 661, in __connect
    self.dbapi_connection = connection = pool._invoke_creator(self)
  File "C:\Users\user\.virtualenvs\kpasec22-pTKp68im\lib\site-packages\sqlalchemy\engine\create.py", line 590, in connect
    return dialect.connect(*cargs, **cparams)
  File "C:\Users\user\.virtualenvs\kpasec22-pTKp68im\lib\site-packages\sqlalchemy\engine\default.py", line 597, in connect
    return self.dbapi.connect(*cargs, **cparams)
  File "C:\Users\user\.virtualenvs\kpasec22-pTKp68im\lib\site-packages\psycopg2\__init__.py", line 122, in connect
    conn = _connect(dsn, connection_factory=connection_factory, **kwasync)
psycopg2.OperationalError: connection to server at "ec2-44-192-245-97.compute-1.amazonaws.com" (44.192.245.97), port 5432 failed: FATAL:  password authentication failed for user "rcrcittfbiapfa"
connection to server at "ec2-44-192-245-97.compute-1.amazonaws.com" (44.192.245.97), port 5432 failed: FATAL:  no pg_hba.conf entry for host "102.176.94.136", user "rcrcittfbiapfa", database "da8kfqt02ehgca", SSL off


The above exception was the direct cause of the following exception:

Traceback (most recent call last):
  File "C:\Users\user\.virtualenvs\kpasec22-pTKp68im\lib\site-packages\flask\app.py", line 2073, in wsgi_app
    response = self.full_dispatch_request()
  File "C:\Users\user\.virtualenvs\kpasec22-pTKp68im\lib\site-packages\flask\app.py", line 1518, in full_dispatch_request
    rv = self.handle_user_exception(e)
  File "C:\Users\user\.virtualenvs\kpasec22-pTKp68im\lib\site-packages\flask\app.py", line 1516, in full_dispatch_request
    rv = self.dispatch_request()
  File "C:\Users\user\.virtualenvs\kpasec22-pTKp68im\lib\site-packages\flask\app.py", line 1502, in dispatch_request
    return self.ensure_sync(self.view_functions[rule.endpoint])(**req.view_args)
  File "C:\Users\user\.virtualenvs\kpasec22-pTKp68im\lib\site-packages\flask_login\utils.py", line 270, in decorated_view
    elif not current_user.is_authenticated:
  File "C:\Users\user\.virtualenvs\kpasec22-pTKp68im\lib\site-packages\werkzeug\local.py", line 436, in __get__
    obj = instance._get_current_object()
  File "C:\Users\user\.virtualenvs\kpasec22-pTKp68im\lib\site-packages\werkzeug\local.py", line 565, in _get_current_object
    return self.__local()  # type: ignore
  File "C:\Users\user\.virtualenvs\kpasec22-pTKp68im\lib\site-packages\flask_login\utils.py", line 26, in <lambda>
    current_user = LocalProxy(lambda: _get_user())
  File "C:\Users\user\.virtualenvs\kpasec22-pTKp68im\lib\site-packages\flask_login\utils.py", line 346, in _get_user
    current_app.login_manager._load_user()
  File "C:\Users\user\.virtualenvs\kpasec22-pTKp68im\lib\site-packages\flask_login\login_manager.py", line 318, in _load_user
    user = self._user_callback(user_id)
  File "C:\Users\user\Desktop\kpasec22\app.py", line 132, in load_user
    return User.query.get(int(user_id))
  File "<string>", line 2, in get
  File "C:\Users\user\.virtualenvs\kpasec22-pTKp68im\lib\site-packages\sqlalchemy\util\deprecations.py", line 401, in warned
    return fn(*args, **kwargs)
  File "C:\Users\user\.virtualenvs\kpasec22-pTKp68im\lib\site-packages\sqlalchemy\orm\query.py", line 943, in get
    return self._get_impl(ident, loading.load_on_pk_identity)
  File "C:\Users\user\.virtualenvs\kpasec22-pTKp68im\lib\site-packages\sqlalchemy\orm\query.py", line 947, in _get_impl
    return self.session._get_impl(
  File "C:\Users\user\.virtualenvs\kpasec22-pTKp68im\lib\site-packages\sqlalchemy\orm\session.py", line 2892, in _get_impl
    return db_load_fn(
  File "C:\Users\user\.virtualenvs\kpasec22-pTKp68im\lib\site-packages\sqlalchemy\orm\loading.py", line 530, in load_on_pk_identity
    session.execute(
  File "C:\Users\user\.virtualenvs\kpasec22-pTKp68im\lib\site-packages\sqlalchemy\orm\session.py", line 1691, in execute
    conn = self._connection_for_bind(bind)
  File "C:\Users\user\.virtualenvs\kpasec22-pTKp68im\lib\site-packages\sqlalchemy\orm\session.py", line 1532, in _connection_for_bind
    return self._transaction._connection_for_bind(
  File "C:\Users\user\.virtualenvs\kpasec22-pTKp68im\lib\site-packages\sqlalchemy\orm\session.py", line 747, in _connection_for_bind
    conn = bind.connect()
  File "C:\Users\user\.virtualenvs\kpasec22-pTKp68im\lib\site-packages\sqlalchemy\engine\base.py", line 3210, in connect
    return self._connection_cls(self, close_with_result=close_with_result)
  File "C:\Users\user\.virtualenvs\kpasec22-pTKp68im\lib\site-packages\sqlalchemy\engine\base.py", line 96, in __init__
    else engine.raw_connection()
  File "C:\Users\user\.virtualenvs\kpasec22-pTKp68im\lib\site-packages\sqlalchemy\engine\base.py", line 3289, in raw_connection
    return self._wrap_pool_connect(self.pool.connect, _connection)
  File "C:\Users\user\.virtualenvs\kpasec22-pTKp68im\lib\site-packages\sqlalchemy\engine\base.py", line 3259, in _wrap_pool_connect
    Connection._handle_dbapi_exception_noconnection(
  File "C:\Users\user\.virtualenvs\kpasec22-pTKp68im\lib\site-packages\sqlalchemy\engine\base.py", line 2106, in _handle_dbapi_exception_noconnection
    util.raise_(
  File "C:\Users\user\.virtualenvs\kpasec22-pTKp68im\lib\site-packages\sqlalchemy\util\compat.py", line 207, in raise_
    raise exception
  File "C:\Users\user\.virtualenvs\kpasec22-pTKp68im\lib\site-packages\sqlalchemy\engine\base.py", line 3256, in _wrap_pool_connect
    return fn()
  File "C:\Users\user\.virtualenvs\kpasec22-pTKp68im\lib\site-packages\sqlalchemy\pool\base.py", line 310, in connect
    return _ConnectionFairy._checkout(self)
  File "C:\Users\user\.virtualenvs\kpasec22-pTKp68im\lib\site-packages\sqlalchemy\pool\base.py", line 868, in _checkout
    fairy = _ConnectionRecord.checkout(pool)
  File "C:\Users\user\.virtualenvs\kpasec22-pTKp68im\lib\site-packages\sqlalchemy\pool\base.py", line 476, in checkout
    rec = pool._do_get()
  File "C:\Users\user\.virtualenvs\kpasec22-pTKp68im\lib\site-packages\sqlalchemy\pool\impl.py", line 146, in _do_get
    self._dec_overflow()
  File "C:\Users\user\.virtualenvs\kpasec22-pTKp68im\lib\site-packages\sqlalchemy\util\langhelpers.py", line 70, in __exit__
    compat.raise_(
  File "C:\Users\user\.virtualenvs\kpasec22-pTKp68im\lib\site-packages\sqlalchemy\util\compat.py", line 207, in raise_
    raise exception
  File "C:\Users\user\.virtualenvs\kpasec22-pTKp68im\lib\site-packages\sqlalchemy\pool\impl.py", line 143, in _do_get
    return self._create_connection()
  File "C:\Users\user\.virtualenvs\kpasec22-pTKp68im\lib\site-packages\sqlalchemy\pool\base.py", line 256, in _create_connection
    return _ConnectionRecord(self)
  File "C:\Users\user\.virtualenvs\kpasec22-pTKp68im\lib\site-packages\sqlalchemy\pool\base.py", line 371, in __init__
    self.__connect()
  File "C:\Users\user\.virtualenvs\kpasec22-pTKp68im\lib\site-packages\sqlalchemy\pool\base.py", line 666, in __connect
    pool.logger.debug("Error on connect(): %s", e)
  File "C:\Users\user\.virtualenvs\kpasec22-pTKp68im\lib\site-packages\sqlalchemy\util\langhelpers.py", line 70, in __exit__
    compat.raise_(
  File "C:\Users\user\.virtualenvs\kpasec22-pTKp68im\lib\site-packages\sqlalchemy\util\compat.py", line 207, in raise_
    raise exception
  File "C:\Users\user\.virtualenvs\kpasec22-pTKp68im\lib\site-packages\sqlalchemy\pool\base.py", line 661, in __connect
    self.dbapi_connection = connection = pool._invoke_creator(self)
  File "C:\Users\user\.virtualenvs\kpasec22-pTKp68im\lib\site-packages\sqlalchemy\engine\create.py", line 590, in connect
    return dialect.connect(*cargs, **cparams)
  File "C:\Users\user\.virtualenvs\kpasec22-pTKp68im\lib\site-packages\sqlalchemy\engine\default.py", line 597, in connect
    return self.dbapi.connect(*cargs, **cparams)
  File "C:\Users\user\.virtualenvs\kpasec22-pTKp68im\lib\site-packages\psycopg2\__init__.py", line 122, in connect
    conn = _connect(dsn, connection_factory=connection_factory, **kwasync)
sqlalchemy.exc.OperationalError: (psycopg2.OperationalError) connection to server at "ec2-44-192-245-97.compute-1.amazonaws.com" (44.192.245.97), port 5432 failed: FATAL:  password authentication failed for user "rcrcittfbiapfa"
connection to server at "ec2-44-192-245-97.compute-1.amazonaws.com" (44.192.245.97), port 5432 failed: FATAL:  no pg_hba.conf entry for host "102.176.94.136", user "rcrcittfbiapfa", database "da8kfqt02ehgca", SSL off

(Background on this error at: https://sqlalche.me/e/14/e3q8)
Exception on /clerk_dashboard [GET]
Traceback (most recent call last):
  File "C:\Users\user\.virtualenvs\kpasec22-pTKp68im\lib\site-packages\sqlalchemy\engine\base.py", line 3256, in _wrap_pool_connect
    return fn()
  File "C:\Users\user\.virtualenvs\kpasec22-pTKp68im\lib\site-packages\sqlalchemy\pool\base.py", line 310, in connect
    return _ConnectionFairy._checkout(self)
  File "C:\Users\user\.virtualenvs\kpasec22-pTKp68im\lib\site-packages\sqlalchemy\pool\base.py", line 868, in _checkout
    fairy = _ConnectionRecord.checkout(pool)
  File "C:\Users\user\.virtualenvs\kpasec22-pTKp68im\lib\site-packages\sqlalchemy\pool\base.py", line 476, in checkout
    rec = pool._do_get()
  File "C:\Users\user\.virtualenvs\kpasec22-pTKp68im\lib\site-packages\sqlalchemy\pool\impl.py", line 146, in _do_get
    self._dec_overflow()
  File "C:\Users\user\.virtualenvs\kpasec22-pTKp68im\lib\site-packages\sqlalchemy\util\langhelpers.py", line 70, in __exit__
    compat.raise_(
  File "C:\Users\user\.virtualenvs\kpasec22-pTKp68im\lib\site-packages\sqlalchemy\util\compat.py", line 207, in raise_
    raise exception
  File "C:\Users\user\.virtualenvs\kpasec22-pTKp68im\lib\site-packages\sqlalchemy\pool\impl.py", line 143, in _do_get
    return self._create_connection()
  File "C:\Users\user\.virtualenvs\kpasec22-pTKp68im\lib\site-packages\sqlalchemy\pool\base.py", line 256, in _create_connection
    return _ConnectionRecord(self)
  File "C:\Users\user\.virtualenvs\kpasec22-pTKp68im\lib\site-packages\sqlalchemy\pool\base.py", line 371, in __init__
    self.__connect()
  File "C:\Users\user\.virtualenvs\kpasec22-pTKp68im\lib\site-packages\sqlalchemy\pool\base.py", line 666, in __connect
    pool.logger.debug("Error on connect(): %s", e)
  File "C:\Users\user\.virtualenvs\kpasec22-pTKp68im\lib\site-packages\sqlalchemy\util\langhelpers.py", line 70, in __exit__
    compat.raise_(
  File "C:\Users\user\.virtualenvs\kpasec22-pTKp68im\lib\site-packages\sqlalchemy\util\compat.py", line 207, in raise_
    raise exception
  File "C:\Users\user\.virtualenvs\kpasec22-pTKp68im\lib\site-packages\sqlalchemy\pool\base.py", line 661, in __connect
    self.dbapi_connection = connection = pool._invoke_creator(self)
  File "C:\Users\user\.virtualenvs\kpasec22-pTKp68im\lib\site-packages\sqlalchemy\engine\create.py", line 590, in connect
    return dialect.connect(*cargs, **cparams)
  File "C:\Users\user\.virtualenvs\kpasec22-pTKp68im\lib\site-packages\sqlalchemy\engine\default.py", line 597, in connect
    return self.dbapi.connect(*cargs, **cparams)
  File "C:\Users\user\.virtualenvs\kpasec22-pTKp68im\lib\site-packages\psycopg2\__init__.py", line 122, in connect
    conn = _connect(dsn, connection_factory=connection_factory, **kwasync)
psycopg2.OperationalError: connection to server at "ec2-44-192-245-97.compute-1.amazonaws.com" (44.192.245.97), port 5432 failed: FATAL:  password authentication failed for user "rcrcittfbiapfa"
connection to server at "ec2-44-192-245-97.compute-1.amazonaws.com" (44.192.245.97), port 5432 failed: FATAL:  no pg_hba.conf entry for host "102.176.94.136", user "rcrcittfbiapfa", database "da8kfqt02ehgca", SSL off


The above exception was the direct cause of the following exception:

Traceback (most recent call last):
  File "C:\Users\user\.virtualenvs\kpasec22-pTKp68im\lib\site-packages\flask\app.py", line 2073, in wsgi_app
    response = self.full_dispatch_request()
  File "C:\Users\user\.virtualenvs\kpasec22-pTKp68im\lib\site-packages\flask\app.py", line 1518, in full_dispatch_request
    rv = self.handle_user_exception(e)
  File "C:\Users\user\.virtualenvs\kpasec22-pTKp68im\lib\site-packages\flask\app.py", line 1516, in full_dispatch_request
    rv = self.dispatch_request()
  File "C:\Users\user\.virtualenvs\kpasec22-pTKp68im\lib\site-packages\flask\app.py", line 1502, in dispatch_request
    return self.ensure_sync(self.view_functions[rule.endpoint])(**req.view_args)
  File "C:\Users\user\.virtualenvs\kpasec22-pTKp68im\lib\site-packages\flask_login\utils.py", line 270, in decorated_view
    elif not current_user.is_authenticated:
  File "C:\Users\user\.virtualenvs\kpasec22-pTKp68im\lib\site-packages\werkzeug\local.py", line 436, in __get__
    obj = instance._get_current_object()
  File "C:\Users\user\.virtualenvs\kpasec22-pTKp68im\lib\site-packages\werkzeug\local.py", line 565, in _get_current_object
    return self.__local()  # type: ignore
  File "C:\Users\user\.virtualenvs\kpasec22-pTKp68im\lib\site-packages\flask_login\utils.py", line 26, in <lambda>
    current_user = LocalProxy(lambda: _get_user())
  File "C:\Users\user\.virtualenvs\kpasec22-pTKp68im\lib\site-packages\flask_login\utils.py", line 346, in _get_user
    current_app.login_manager._load_user()
  File "C:\Users\user\.virtualenvs\kpasec22-pTKp68im\lib\site-packages\flask_login\login_manager.py", line 318, in _load_user
    user = self._user_callback(user_id)
  File "C:\Users\user\Desktop\kpasec22\app.py", line 132, in load_user
    return User.query.get(int(user_id))
  File "<string>", line 2, in get
  File "C:\Users\user\.virtualenvs\kpasec22-pTKp68im\lib\site-packages\sqlalchemy\util\deprecations.py", line 401, in warned
    return fn(*args, **kwargs)
  File "C:\Users\user\.virtualenvs\kpasec22-pTKp68im\lib\site-packages\sqlalchemy\orm\query.py", line 943, in get
    return self._get_impl(ident, loading.load_on_pk_identity)
  File "C:\Users\user\.virtualenvs\kpasec22-pTKp68im\lib\site-packages\sqlalchemy\orm\query.py", line 947, in _get_impl
    return self.session._get_impl(
  File "C:\Users\user\.virtualenvs\kpasec22-pTKp68im\lib\site-packages\sqlalchemy\orm\session.py", line 2892, in _get_impl
    return db_load_fn(
  File "C:\Users\user\.virtualenvs\kpasec22-pTKp68im\lib\site-packages\sqlalchemy\orm\loading.py", line 530, in load_on_pk_identity
    session.execute(
  File "C:\Users\user\.virtualenvs\kpasec22-pTKp68im\lib\site-packages\sqlalchemy\orm\session.py", line 1691, in execute
    conn = self._connection_for_bind(bind)
  File "C:\Users\user\.virtualenvs\kpasec22-pTKp68im\lib\site-packages\sqlalchemy\orm\session.py", line 1532, in _connection_for_bind
    return self._transaction._connection_for_bind(
  File "C:\Users\user\.virtualenvs\kpasec22-pTKp68im\lib\site-packages\sqlalchemy\orm\session.py", line 747, in _connection_for_bind
    conn = bind.connect()
  File "C:\Users\user\.virtualenvs\kpasec22-pTKp68im\lib\site-packages\sqlalchemy\engine\base.py", line 3210, in connect
    return self._connection_cls(self, close_with_result=close_with_result)
  File "C:\Users\user\.virtualenvs\kpasec22-pTKp68im\lib\site-packages\sqlalchemy\engine\base.py", line 96, in __init__
    else engine.raw_connection()
  File "C:\Users\user\.virtualenvs\kpasec22-pTKp68im\lib\site-packages\sqlalchemy\engine\base.py", line 3289, in raw_connection
    return self._wrap_pool_connect(self.pool.connect, _connection)
  File "C:\Users\user\.virtualenvs\kpasec22-pTKp68im\lib\site-packages\sqlalchemy\engine\base.py", line 3259, in _wrap_pool_connect
    Connection._handle_dbapi_exception_noconnection(
  File "C:\Users\user\.virtualenvs\kpasec22-pTKp68im\lib\site-packages\sqlalchemy\engine\base.py", line 2106, in _handle_dbapi_exception_noconnection
    util.raise_(
  File "C:\Users\user\.virtualenvs\kpasec22-pTKp68im\lib\site-packages\sqlalchemy\util\compat.py", line 207, in raise_
    raise exception
  File "C:\Users\user\.virtualenvs\kpasec22-pTKp68im\lib\site-packages\sqlalchemy\engine\base.py", line 3256, in _wrap_pool_connect
    return fn()
  File "C:\Users\user\.virtualenvs\kpasec22-pTKp68im\lib\site-packages\sqlalchemy\pool\base.py", line 310, in connect
    return _ConnectionFairy._checkout(self)
  File "C:\Users\user\.virtualenvs\kpasec22-pTKp68im\lib\site-packages\sqlalchemy\pool\base.py", line 868, in _checkout
    fairy = _ConnectionRecord.checkout(pool)
  File "C:\Users\user\.virtualenvs\kpasec22-pTKp68im\lib\site-packages\sqlalchemy\pool\base.py", line 476, in checkout
    rec = pool._do_get()
  File "C:\Users\user\.virtualenvs\kpasec22-pTKp68im\lib\site-packages\sqlalchemy\pool\impl.py", line 146, in _do_get
    self._dec_overflow()
  File "C:\Users\user\.virtualenvs\kpasec22-pTKp68im\lib\site-packages\sqlalchemy\util\langhelpers.py", line 70, in __exit__
    compat.raise_(
  File "C:\Users\user\.virtualenvs\kpasec22-pTKp68im\lib\site-packages\sqlalchemy\util\compat.py", line 207, in raise_
    raise exception
  File "C:\Users\user\.virtualenvs\kpasec22-pTKp68im\lib\site-packages\sqlalchemy\pool\impl.py", line 143, in _do_get
    return self._create_connection()
  File "C:\Users\user\.virtualenvs\kpasec22-pTKp68im\lib\site-packages\sqlalchemy\pool\base.py", line 256, in _create_connection
    return _ConnectionRecord(self)
  File "C:\Users\user\.virtualenvs\kpasec22-pTKp68im\lib\site-packages\sqlalchemy\pool\base.py", line 371, in __init__
    self.__connect()
  File "C:\Users\user\.virtualenvs\kpasec22-pTKp68im\lib\site-packages\sqlalchemy\pool\base.py", line 666, in __connect
    pool.logger.debug("Error on connect(): %s", e)
  File "C:\Users\user\.virtualenvs\kpasec22-pTKp68im\lib\site-packages\sqlalchemy\util\langhelpers.py", line 70, in __exit__
    compat.raise_(
  File "C:\Users\user\.virtualenvs\kpasec22-pTKp68im\lib\site-packages\sqlalchemy\util\compat.py", line 207, in raise_
    raise exception
  File "C:\Users\user\.virtualenvs\kpasec22-pTKp68im\lib\site-packages\sqlalchemy\pool\base.py", line 661, in __connect
    self.dbapi_connection = connection = pool._invoke_creator(self)
  File "C:\Users\user\.virtualenvs\kpasec22-pTKp68im\lib\site-packages\sqlalchemy\engine\create.py", line 590, in connect
    return dialect.connect(*cargs, **cparams)
  File "C:\Users\user\.virtualenvs\kpasec22-pTKp68im\lib\site-packages\sqlalchemy\engine\default.py", line 597, in connect
    return self.dbapi.connect(*cargs, **cparams)
  File "C:\Users\user\.virtualenvs\kpasec22-pTKp68im\lib\site-packages\psycopg2\__init__.py", line 122, in connect
    conn = _connect(dsn, connection_factory=connection_factory, **kwasync)
sqlalchemy.exc.OperationalError: (psycopg2.OperationalError) connection to server at "ec2-44-192-245-97.compute-1.amazonaws.com" (44.192.245.97), port 5432 failed: FATAL:  password authentication failed for user "rcrcittfbiapfa"
connection to server at "ec2-44-192-245-97.compute-1.amazonaws.com" (44.192.245.97), port 5432 failed: FATAL:  no pg_hba.conf entry for host "102.176.94.136", user "rcrcittfbiapfa", database "da8kfqt02ehgca", SSL off

(Background on this error at: https://sqlalche.me/e/14/e3q8)
Exception on /accountant_dashboard [GET]
Traceback (most recent call last):
  File "C:\Users\user\.virtualenvs\kpasec22-pTKp68im\lib\site-packages\sqlalchemy\engine\base.py", line 3280, in _wrap_pool_connect
    return fn()
  File "C:\Users\user\.virtualenvs\kpasec22-pTKp68im\lib\site-packages\sqlalchemy\pool\base.py", line 310, in connect
    return _ConnectionFairy._checkout(self)
  File "C:\Users\user\.virtualenvs\kpasec22-pTKp68im\lib\site-packages\sqlalchemy\pool\base.py", line 868, in _checkout
    fairy = _ConnectionRecord.checkout(pool)
  File "C:\Users\user\.virtualenvs\kpasec22-pTKp68im\lib\site-packages\sqlalchemy\pool\base.py", line 476, in checkout
    rec = pool._do_get()
  File "C:\Users\user\.virtualenvs\kpasec22-pTKp68im\lib\site-packages\sqlalchemy\pool\impl.py", line 146, in _do_get
    self._dec_overflow()
  File "C:\Users\user\.virtualenvs\kpasec22-pTKp68im\lib\site-packages\sqlalchemy\util\langhelpers.py", line 70, in __exit__
    compat.raise_(
  File "C:\Users\user\.virtualenvs\kpasec22-pTKp68im\lib\site-packages\sqlalchemy\util\compat.py", line 207, in raise_
    raise exception
  File "C:\Users\user\.virtualenvs\kpasec22-pTKp68im\lib\site-packages\sqlalchemy\pool\impl.py", line 143, in _do_get
    return self._create_connection()
  File "C:\Users\user\.virtualenvs\kpasec22-pTKp68im\lib\site-packages\sqlalchemy\pool\base.py", line 256, in _create_connection
    return _ConnectionRecord(self)
  File "C:\Users\user\.virtualenvs\kpasec22-pTKp68im\lib\site-packages\sqlalchemy\pool\base.py", line 371, in __init__
    self.__connect()
  File "C:\Users\user\.virtualenvs\kpasec22-pTKp68im\lib\site-packages\sqlalchemy\pool\base.py", line 666, in __connect
    pool.logger.debug("Error on connect(): %s", e)
  File "C:\Users\user\.virtualenvs\kpasec22-pTKp68im\lib\site-packages\sqlalchemy\util\langhelpers.py", line 70, in __exit__
    compat.raise_(
  File "C:\Users\user\.virtualenvs\kpasec22-pTKp68im\lib\site-packages\sqlalchemy\util\compat.py", line 207, in raise_
    raise exception
  File "C:\Users\user\.virtualenvs\kpasec22-pTKp68im\lib\site-packages\sqlalchemy\pool\base.py", line 661, in __connect
    self.dbapi_connection = connection = pool._invoke_creator(self)
  File "C:\Users\user\.virtualenvs\kpasec22-pTKp68im\lib\site-packages\sqlalchemy\engine\create.py", line 590, in connect
    return dialect.connect(*cargs, **cparams)
  File "C:\Users\user\.virtualenvs\kpasec22-pTKp68im\lib\site-packages\sqlalchemy\engine\default.py", line 597, in connect
    return self.dbapi.connect(*cargs, **cparams)
  File "C:\Users\user\.virtualenvs\kpasec22-pTKp68im\lib\site-packages\psycopg2\__init__.py", line 122, in connect
    conn = _connect(dsn, connection_factory=connection_factory, **kwasync)
psycopg2.OperationalError: connection to server at "ec2-44-192-245-97.compute-1.amazonaws.com" (44.192.245.97), port 5432 failed: FATAL:  password authentication failed for user "rcrcittfbiapfa"
connection to server at "ec2-44-192-245-97.compute-1.amazonaws.com" (44.192.245.97), port 5432 failed: FATAL:  no pg_hba.conf entry for host "102.176.65.190", user "rcrcittfbiapfa", database "da8kfqt02ehgca", SSL off


The above exception was the direct cause of the following exception:

Traceback (most recent call last):
  File "C:\Users\user\.virtualenvs\kpasec22-pTKp68im\lib\site-packages\flask\app.py", line 2077, in wsgi_app
    response = self.full_dispatch_request()
  File "C:\Users\user\.virtualenvs\kpasec22-pTKp68im\lib\site-packages\flask\app.py", line 1525, in full_dispatch_request
    rv = self.handle_user_exception(e)
  File "C:\Users\user\.virtualenvs\kpasec22-pTKp68im\lib\site-packages\flask\app.py", line 1523, in full_dispatch_request
    rv = self.dispatch_request()
  File "C:\Users\user\.virtualenvs\kpasec22-pTKp68im\lib\site-packages\flask\app.py", line 1509, in dispatch_request
    return self.ensure_sync(self.view_functions[rule.endpoint])(**req.view_args)
  File "C:\Users\user\.virtualenvs\kpasec22-pTKp68im\lib\site-packages\flask_login\utils.py", line 273, in decorated_view
    elif not current_user.is_authenticated:
  File "C:\Users\user\.virtualenvs\kpasec22-pTKp68im\lib\site-packages\werkzeug\local.py", line 278, in __get__
    obj = instance._get_current_object()
  File "C:\Users\user\.virtualenvs\kpasec22-pTKp68im\lib\site-packages\werkzeug\local.py", line 407, in _get_current_object
    return self.__local()  # type: ignore
  File "C:\Users\user\.virtualenvs\kpasec22-pTKp68im\lib\site-packages\flask_login\utils.py", line 25, in <lambda>
    current_user = LocalProxy(lambda: _get_user())
  File "C:\Users\user\.virtualenvs\kpasec22-pTKp68im\lib\site-packages\flask_login\utils.py", line 359, in _get_user
    current_app.login_manager._load_user()
  File "C:\Users\user\.virtualenvs\kpasec22-pTKp68im\lib\site-packages\flask_login\login_manager.py", line 355, in _load_user
    user = self._user_callback(user_id)
  File "C:\Users\user\Desktop\kpasec22\app.py", line 130, in load_user
    return User.query.get(int(user_id))
  File "<string>", line 2, in get
  File "C:\Users\user\.virtualenvs\kpasec22-pTKp68im\lib\site-packages\sqlalchemy\util\deprecations.py", line 401, in warned
    return fn(*args, **kwargs)
  File "C:\Users\user\.virtualenvs\kpasec22-pTKp68im\lib\site-packages\sqlalchemy\orm\query.py", line 943, in get
    return self._get_impl(ident, loading.load_on_pk_identity)
  File "C:\Users\user\.virtualenvs\kpasec22-pTKp68im\lib\site-packages\sqlalchemy\orm\query.py", line 947, in _get_impl
    return self.session._get_impl(
  File "C:\Users\user\.virtualenvs\kpasec22-pTKp68im\lib\site-packages\sqlalchemy\orm\session.py", line 2892, in _get_impl
    return db_load_fn(
  File "C:\Users\user\.virtualenvs\kpasec22-pTKp68im\lib\site-packages\sqlalchemy\orm\loading.py", line 530, in load_on_pk_identity
    session.execute(
  File "C:\Users\user\.virtualenvs\kpasec22-pTKp68im\lib\site-packages\sqlalchemy\orm\session.py", line 1691, in execute
    conn = self._connection_for_bind(bind)
  File "C:\Users\user\.virtualenvs\kpasec22-pTKp68im\lib\site-packages\sqlalchemy\orm\session.py", line 1532, in _connection_for_bind
    return self._transaction._connection_for_bind(
  File "C:\Users\user\.virtualenvs\kpasec22-pTKp68im\lib\site-packages\sqlalchemy\orm\session.py", line 747, in _connection_for_bind
    conn = bind.connect()
  File "C:\Users\user\.virtualenvs\kpasec22-pTKp68im\lib\site-packages\sqlalchemy\engine\base.py", line 3234, in connect
    return self._connection_cls(self, close_with_result=close_with_result)
  File "C:\Users\user\.virtualenvs\kpasec22-pTKp68im\lib\site-packages\sqlalchemy\engine\base.py", line 96, in __init__
    else engine.raw_connection()
  File "C:\Users\user\.virtualenvs\kpasec22-pTKp68im\lib\site-packages\sqlalchemy\engine\base.py", line 3313, in raw_connection
    return self._wrap_pool_connect(self.pool.connect, _connection)
  File "C:\Users\user\.virtualenvs\kpasec22-pTKp68im\lib\site-packages\sqlalchemy\engine\base.py", line 3283, in _wrap_pool_connect
    Connection._handle_dbapi_exception_noconnection(
  File "C:\Users\user\.virtualenvs\kpasec22-pTKp68im\lib\site-packages\sqlalchemy\engine\base.py", line 2117, in _handle_dbapi_exception_noconnection
    util.raise_(
  File "C:\Users\user\.virtualenvs\kpasec22-pTKp68im\lib\site-packages\sqlalchemy\util\compat.py", line 207, in raise_
    raise exception
  File "C:\Users\user\.virtualenvs\kpasec22-pTKp68im\lib\site-packages\sqlalchemy\engine\base.py", line 3280, in _wrap_pool_connect
    return fn()
  File "C:\Users\user\.virtualenvs\kpasec22-pTKp68im\lib\site-packages\sqlalchemy\pool\base.py", line 310, in connect
    return _ConnectionFairy._checkout(self)
  File "C:\Users\user\.virtualenvs\kpasec22-pTKp68im\lib\site-packages\sqlalchemy\pool\base.py", line 868, in _checkout
    fairy = _ConnectionRecord.checkout(pool)
  File "C:\Users\user\.virtualenvs\kpasec22-pTKp68im\lib\site-packages\sqlalchemy\pool\base.py", line 476, in checkout
    rec = pool._do_get()
  File "C:\Users\user\.virtualenvs\kpasec22-pTKp68im\lib\site-packages\sqlalchemy\pool\impl.py", line 146, in _do_get
    self._dec_overflow()
  File "C:\Users\user\.virtualenvs\kpasec22-pTKp68im\lib\site-packages\sqlalchemy\util\langhelpers.py", line 70, in __exit__
    compat.raise_(
  File "C:\Users\user\.virtualenvs\kpasec22-pTKp68im\lib\site-packages\sqlalchemy\util\compat.py", line 207, in raise_
    raise exception
  File "C:\Users\user\.virtualenvs\kpasec22-pTKp68im\lib\site-packages\sqlalchemy\pool\impl.py", line 143, in _do_get
    return self._create_connection()
  File "C:\Users\user\.virtualenvs\kpasec22-pTKp68im\lib\site-packages\sqlalchemy\pool\base.py", line 256, in _create_connection
    return _ConnectionRecord(self)
  File "C:\Users\user\.virtualenvs\kpasec22-pTKp68im\lib\site-packages\sqlalchemy\pool\base.py", line 371, in __init__
    self.__connect()
  File "C:\Users\user\.virtualenvs\kpasec22-pTKp68im\lib\site-packages\sqlalchemy\pool\base.py", line 666, in __connect
    pool.logger.debug("Error on connect(): %s", e)
  File "C:\Users\user\.virtualenvs\kpasec22-pTKp68im\lib\site-packages\sqlalchemy\util\langhelpers.py", line 70, in __exit__
    compat.raise_(
  File "C:\Users\user\.virtualenvs\kpasec22-pTKp68im\lib\site-packages\sqlalchemy\util\compat.py", line 207, in raise_
    raise exception
  File "C:\Users\user\.virtualenvs\kpasec22-pTKp68im\lib\site-packages\sqlalchemy\pool\base.py", line 661, in __connect
    self.dbapi_connection = connection = pool._invoke_creator(self)
  File "C:\Users\user\.virtualenvs\kpasec22-pTKp68im\lib\site-packages\sqlalchemy\engine\create.py", line 590, in connect
    return dialect.connect(*cargs, **cparams)
  File "C:\Users\user\.virtualenvs\kpasec22-pTKp68im\lib\site-packages\sqlalchemy\engine\default.py", line 597, in connect
    return self.dbapi.connect(*cargs, **cparams)
  File "C:\Users\user\.virtualenvs\kpasec22-pTKp68im\lib\site-packages\psycopg2\__init__.py", line 122, in connect
    conn = _connect(dsn, connection_factory=connection_factory, **kwasync)
sqlalchemy.exc.OperationalError: (psycopg2.OperationalError) connection to server at "ec2-44-192-245-97.compute-1.amazonaws.com" (44.192.245.97), port 5432 failed: FATAL:  password authentication failed for user "rcrcittfbiapfa"
connection to server at "ec2-44-192-245-97.compute-1.amazonaws.com" (44.192.245.97), port 5432 failed: FATAL:  no pg_hba.conf entry for host "102.176.65.190", user "rcrcittfbiapfa", database "da8kfqt02ehgca", SSL off

(Background on this error at: https://sqlalche.me/e/14/e3q8)
Exception on /admin/student/ [GET]
Traceback (most recent call last):
  File "C:\Users\user\.virtualenvs\kpasec22-pTKp68im\lib\site-packages\sqlalchemy\engine\base.py", line 3280, in _wrap_pool_connect
    return fn()
  File "C:\Users\user\.virtualenvs\kpasec22-pTKp68im\lib\site-packages\sqlalchemy\pool\base.py", line 310, in connect
    return _ConnectionFairy._checkout(self)
  File "C:\Users\user\.virtualenvs\kpasec22-pTKp68im\lib\site-packages\sqlalchemy\pool\base.py", line 868, in _checkout
    fairy = _ConnectionRecord.checkout(pool)
  File "C:\Users\user\.virtualenvs\kpasec22-pTKp68im\lib\site-packages\sqlalchemy\pool\base.py", line 476, in checkout
    rec = pool._do_get()
  File "C:\Users\user\.virtualenvs\kpasec22-pTKp68im\lib\site-packages\sqlalchemy\pool\impl.py", line 146, in _do_get
    self._dec_overflow()
  File "C:\Users\user\.virtualenvs\kpasec22-pTKp68im\lib\site-packages\sqlalchemy\util\langhelpers.py", line 70, in __exit__
    compat.raise_(
  File "C:\Users\user\.virtualenvs\kpasec22-pTKp68im\lib\site-packages\sqlalchemy\util\compat.py", line 207, in raise_
    raise exception
  File "C:\Users\user\.virtualenvs\kpasec22-pTKp68im\lib\site-packages\sqlalchemy\pool\impl.py", line 143, in _do_get
    return self._create_connection()
  File "C:\Users\user\.virtualenvs\kpasec22-pTKp68im\lib\site-packages\sqlalchemy\pool\base.py", line 256, in _create_connection
    return _ConnectionRecord(self)
  File "C:\Users\user\.virtualenvs\kpasec22-pTKp68im\lib\site-packages\sqlalchemy\pool\base.py", line 371, in __init__
    self.__connect()
  File "C:\Users\user\.virtualenvs\kpasec22-pTKp68im\lib\site-packages\sqlalchemy\pool\base.py", line 666, in __connect
    pool.logger.debug("Error on connect(): %s", e)
  File "C:\Users\user\.virtualenvs\kpasec22-pTKp68im\lib\site-packages\sqlalchemy\util\langhelpers.py", line 70, in __exit__
    compat.raise_(
  File "C:\Users\user\.virtualenvs\kpasec22-pTKp68im\lib\site-packages\sqlalchemy\util\compat.py", line 207, in raise_
    raise exception
  File "C:\Users\user\.virtualenvs\kpasec22-pTKp68im\lib\site-packages\sqlalchemy\pool\base.py", line 661, in __connect
    self.dbapi_connection = connection = pool._invoke_creator(self)
  File "C:\Users\user\.virtualenvs\kpasec22-pTKp68im\lib\site-packages\sqlalchemy\engine\create.py", line 590, in connect
    return dialect.connect(*cargs, **cparams)
  File "C:\Users\user\.virtualenvs\kpasec22-pTKp68im\lib\site-packages\sqlalchemy\engine\default.py", line 597, in connect
    return self.dbapi.connect(*cargs, **cparams)
  File "C:\Users\user\.virtualenvs\kpasec22-pTKp68im\lib\site-packages\psycopg2\__init__.py", line 122, in connect
    conn = _connect(dsn, connection_factory=connection_factory, **kwasync)
psycopg2.OperationalError: connection to server at "ec2-44-192-245-97.compute-1.amazonaws.com" (44.192.245.97), port 5432 failed: FATAL:  password authentication failed for user "rcrcittfbiapfa"
connection to server at "ec2-44-192-245-97.compute-1.amazonaws.com" (44.192.245.97), port 5432 failed: FATAL:  no pg_hba.conf entry for host "102.176.65.190", user "rcrcittfbiapfa", database "da8kfqt02ehgca", SSL off


The above exception was the direct cause of the following exception:

Traceback (most recent call last):
  File "C:\Users\user\.virtualenvs\kpasec22-pTKp68im\lib\site-packages\flask\app.py", line 2077, in wsgi_app
    response = self.full_dispatch_request()
  File "C:\Users\user\.virtualenvs\kpasec22-pTKp68im\lib\site-packages\flask\app.py", line 1525, in full_dispatch_request
    rv = self.handle_user_exception(e)
  File "C:\Users\user\.virtualenvs\kpasec22-pTKp68im\lib\site-packages\flask\app.py", line 1523, in full_dispatch_request
    rv = self.dispatch_request()
  File "C:\Users\user\.virtualenvs\kpasec22-pTKp68im\lib\site-packages\flask\app.py", line 1509, in dispatch_request
    return self.ensure_sync(self.view_functions[rule.endpoint])(**req.view_args)
  File "C:\Users\user\.virtualenvs\kpasec22-pTKp68im\lib\site-packages\flask_admin\base.py", line 65, in inner
    abort = self._handle_view(f.__name__, **kwargs)
  File "C:\Users\user\.virtualenvs\kpasec22-pTKp68im\lib\site-packages\flask_admin\base.py", line 353, in _handle_view
    if not self.is_accessible():
  File "C:\Users\user\Desktop\kpasec22\app.py", line 1715, in is_accessible
    if current_user.is_authenticated:# and current_user.approval:# and current_user.is_admin:
  File "C:\Users\user\.virtualenvs\kpasec22-pTKp68im\lib\site-packages\werkzeug\local.py", line 278, in __get__
    obj = instance._get_current_object()
  File "C:\Users\user\.virtualenvs\kpasec22-pTKp68im\lib\site-packages\werkzeug\local.py", line 407, in _get_current_object
    return self.__local()  # type: ignore
  File "C:\Users\user\.virtualenvs\kpasec22-pTKp68im\lib\site-packages\flask_login\utils.py", line 25, in <lambda>
    current_user = LocalProxy(lambda: _get_user())
  File "C:\Users\user\.virtualenvs\kpasec22-pTKp68im\lib\site-packages\flask_login\utils.py", line 359, in _get_user
    current_app.login_manager._load_user()
  File "C:\Users\user\.virtualenvs\kpasec22-pTKp68im\lib\site-packages\flask_login\login_manager.py", line 355, in _load_user
    user = self._user_callback(user_id)
  File "C:\Users\user\Desktop\kpasec22\app.py", line 130, in load_user
    return User.query.get(int(user_id))
  File "<string>", line 2, in get
  File "C:\Users\user\.virtualenvs\kpasec22-pTKp68im\lib\site-packages\sqlalchemy\util\deprecations.py", line 401, in warned
    return fn(*args, **kwargs)
  File "C:\Users\user\.virtualenvs\kpasec22-pTKp68im\lib\site-packages\sqlalchemy\orm\query.py", line 943, in get
    return self._get_impl(ident, loading.load_on_pk_identity)
  File "C:\Users\user\.virtualenvs\kpasec22-pTKp68im\lib\site-packages\sqlalchemy\orm\query.py", line 947, in _get_impl
    return self.session._get_impl(
  File "C:\Users\user\.virtualenvs\kpasec22-pTKp68im\lib\site-packages\sqlalchemy\orm\session.py", line 2892, in _get_impl
    return db_load_fn(
  File "C:\Users\user\.virtualenvs\kpasec22-pTKp68im\lib\site-packages\sqlalchemy\orm\loading.py", line 530, in load_on_pk_identity
    session.execute(
  File "C:\Users\user\.virtualenvs\kpasec22-pTKp68im\lib\site-packages\sqlalchemy\orm\session.py", line 1691, in execute
    conn = self._connection_for_bind(bind)
  File "C:\Users\user\.virtualenvs\kpasec22-pTKp68im\lib\site-packages\sqlalchemy\orm\session.py", line 1532, in _connection_for_bind
    return self._transaction._connection_for_bind(
  File "C:\Users\user\.virtualenvs\kpasec22-pTKp68im\lib\site-packages\sqlalchemy\orm\session.py", line 747, in _connection_for_bind
    conn = bind.connect()
  File "C:\Users\user\.virtualenvs\kpasec22-pTKp68im\lib\site-packages\sqlalchemy\engine\base.py", line 3234, in connect
    return self._connection_cls(self, close_with_result=close_with_result)
  File "C:\Users\user\.virtualenvs\kpasec22-pTKp68im\lib\site-packages\sqlalchemy\engine\base.py", line 96, in __init__
    else engine.raw_connection()
  File "C:\Users\user\.virtualenvs\kpasec22-pTKp68im\lib\site-packages\sqlalchemy\engine\base.py", line 3313, in raw_connection
    return self._wrap_pool_connect(self.pool.connect, _connection)
  File "C:\Users\user\.virtualenvs\kpasec22-pTKp68im\lib\site-packages\sqlalchemy\engine\base.py", line 3283, in _wrap_pool_connect
    Connection._handle_dbapi_exception_noconnection(
  File "C:\Users\user\.virtualenvs\kpasec22-pTKp68im\lib\site-packages\sqlalchemy\engine\base.py", line 2117, in _handle_dbapi_exception_noconnection
    util.raise_(
  File "C:\Users\user\.virtualenvs\kpasec22-pTKp68im\lib\site-packages\sqlalchemy\util\compat.py", line 207, in raise_
    raise exception
  File "C:\Users\user\.virtualenvs\kpasec22-pTKp68im\lib\site-packages\sqlalchemy\engine\base.py", line 3280, in _wrap_pool_connect
    return fn()
  File "C:\Users\user\.virtualenvs\kpasec22-pTKp68im\lib\site-packages\sqlalchemy\pool\base.py", line 310, in connect
    return _ConnectionFairy._checkout(self)
  File "C:\Users\user\.virtualenvs\kpasec22-pTKp68im\lib\site-packages\sqlalchemy\pool\base.py", line 868, in _checkout
    fairy = _ConnectionRecord.checkout(pool)
  File "C:\Users\user\.virtualenvs\kpasec22-pTKp68im\lib\site-packages\sqlalchemy\pool\base.py", line 476, in checkout
    rec = pool._do_get()
  File "C:\Users\user\.virtualenvs\kpasec22-pTKp68im\lib\site-packages\sqlalchemy\pool\impl.py", line 146, in _do_get
    self._dec_overflow()
  File "C:\Users\user\.virtualenvs\kpasec22-pTKp68im\lib\site-packages\sqlalchemy\util\langhelpers.py", line 70, in __exit__
    compat.raise_(
  File "C:\Users\user\.virtualenvs\kpasec22-pTKp68im\lib\site-packages\sqlalchemy\util\compat.py", line 207, in raise_
    raise exception
  File "C:\Users\user\.virtualenvs\kpasec22-pTKp68im\lib\site-packages\sqlalchemy\pool\impl.py", line 143, in _do_get
    return self._create_connection()
  File "C:\Users\user\.virtualenvs\kpasec22-pTKp68im\lib\site-packages\sqlalchemy\pool\base.py", line 256, in _create_connection
    return _ConnectionRecord(self)
  File "C:\Users\user\.virtualenvs\kpasec22-pTKp68im\lib\site-packages\sqlalchemy\pool\base.py", line 371, in __init__
    self.__connect()
  File "C:\Users\user\.virtualenvs\kpasec22-pTKp68im\lib\site-packages\sqlalchemy\pool\base.py", line 666, in __connect
    pool.logger.debug("Error on connect(): %s", e)
  File "C:\Users\user\.virtualenvs\kpasec22-pTKp68im\lib\site-packages\sqlalchemy\util\langhelpers.py", line 70, in __exit__
    compat.raise_(
  File "C:\Users\user\.virtualenvs\kpasec22-pTKp68im\lib\site-packages\sqlalchemy\util\compat.py", line 207, in raise_
    raise exception
  File "C:\Users\user\.virtualenvs\kpasec22-pTKp68im\lib\site-packages\sqlalchemy\pool\base.py", line 661, in __connect
    self.dbapi_connection = connection = pool._invoke_creator(self)
  File "C:\Users\user\.virtualenvs\kpasec22-pTKp68im\lib\site-packages\sqlalchemy\engine\create.py", line 590, in connect
    return dialect.connect(*cargs, **cparams)
  File "C:\Users\user\.virtualenvs\kpasec22-pTKp68im\lib\site-packages\sqlalchemy\engine\default.py", line 597, in connect
    return self.dbapi.connect(*cargs, **cparams)
  File "C:\Users\user\.virtualenvs\kpasec22-pTKp68im\lib\site-packages\psycopg2\__init__.py", line 122, in connect
    conn = _connect(dsn, connection_factory=connection_factory, **kwasync)
sqlalchemy.exc.OperationalError: (psycopg2.OperationalError) connection to server at "ec2-44-192-245-97.compute-1.amazonaws.com" (44.192.245.97), port 5432 failed: FATAL:  password authentication failed for user "rcrcittfbiapfa"
connection to server at "ec2-44-192-245-97.compute-1.amazonaws.com" (44.192.245.97), port 5432 failed: FATAL:  no pg_hba.conf entry for host "102.176.65.190", user "rcrcittfbiapfa", database "da8kfqt02ehgca", SSL off

(Background on this error at: https://sqlalche.me/e/14/e3q8)
